Workbook

Sheet DAY1
A1: BOPP STOCK MOVEMENT REPORT FOR OPENING BALANCES FOR SEPTEMBER AS OF 29/8/26
A2: DESCRIPTION AND CODE | B2: OPENING | C2: RECEIPTS | D2: RETURNS | E2: EXCHANGED | F2: SALES | G2: ISSUES | H2: THEORETICAL | I2: PHYSICAL | J2: R/MATERIAL | K2: RECEIPTS TO | L2: RETURNS | M2: EXCHANGED TO | N2: SALES TO | O2: ISSUES TO | P2: AVE RECEIPTS | Q2: AVE RETURNS | R2: AVE EXCHANGED | S2: AVE SALES | T2: AVE ISSUES | U2: STOCK
B3: STOCK | H3: CLOSING STOCK | I3: CLOSING STOCK | J3: VARIANCE | K3: DATE | L3: TO DATE | M3: DATE | N3: DATE | O3: DATE | P3: PER DAY | Q3: PER DAY | R3: PER DAY | T3: PER DAY | U3: DAYS
A4: BOPP : CLEAR & PET
B5: 0 | C5: 0 | D5: 0 | E5: 0 | F5: 0 | G5: 0 | H5: =+(Table1[[#This Row],[OPENING ]]+Table1[[#This Row],[RECEIPTS]]+Table1[[#This Row],[RETURNS]])-(Table1[[#This Row],[ISSUES]]+Table1[[#This Row],[EXCHANGED]]+Table1[[#This Row],[SALES]]) -> 0 | I5: 0 | J5: =+Table1[[#This Row],[PHYSICAL]]-Table1[[#This Row],[THEORETICAL]] -> 0 | K5: =+Table1[[#This Row],[RECEIPTS]] -> 0 | L5: =+Table1[[#This Row],[RETURNS]] -> 0 | M5: =+Table1[[#This Row],[EXCHANGED]] -> 0 | N5: =+Table1[[#This Row],[SALES]] -> 0 | O5: =+Table1[[#This Row],[ISSUES]] -> 0 | P5: =Table1[[#This Row],[RECEIPTS TO]]/1 -> 0 | Q5: =+Table1[[#This Row],[RETURNS ]]/1 -> 0 | R5: =+Table1[[#This Row],[EXCHANGED TO]]/1 -> 0 | S5: =+Table1[[#This Row],[SALES TO]]/1 -> 0 | T5: =+Table1[[#This Row],[ISSUES TO]]/1 -> 0 | U5: =IFERROR(+H5/(P5+Q5+R5+S5+T5),0) -> 0
B6: 0 | C6: 0 | D6: 0 | E6: 0 | F6: 0 | G6: 0 | H6: =+(Table1[[#This Row],[OPENING ]]+Table1[[#This Row],[RECEIPTS]]+Table1[[#This Row],[RETURNS]])-(Table1[[#This Row],[ISSUES]]+Table1[[#This Row],[EXCHANGED]]+Table1[[#This Row],[SALES]]) -> 0 | I6: 0 | J6: =+Table1[[#This Row],[PHYSICAL]]-Table1[[#This Row],[THEORETICAL]] -> 0 | K6: =+Table1[[#This Row],[RECEIPTS]] -> 0 | L6: =+Table1[[#This Row],[RETURNS]] -> 0 | M6: =+Table1[[#This Row],[EXCHANGED]] -> 0 | N6: =+Table1[[#This Row],[SALES]] -> 0 | O6: =+Table1[[#This Row],[ISSUES]] -> 0 | P6: =Table1[[#This Row],[RECEIPTS TO]]/1 -> 0 | Q6: =+Table1[[#This Row],[RETURNS ]]/1 -> 0 | R6: =+Table1[[#This Row],[EXCHANGED TO]]/1 -> 0 | S6: =+Table1[[#This Row],[SALES TO]]/1 -> 0 | T6: =+Table1[[#This Row],[ISSUES TO]]/1 -> 0 | U6: =IFERROR(+H6/(P6+Q6+R6+S6+T6),0) -> 0
B7: 0 | C7: 0 | D7: 0 | E7: 0 | F7: 0 | G7: 0 | H7: =+(Table1[[#This Row],[OPENING ]]+Table1[[#This Row],[RECEIPTS]]+Table1[[#This Row],[RETURNS]])-(Table1[[#This Row],[ISSUES]]+Table1[[#This Row],[EXCHANGED]]+Table1[[#This Row],[SALES]]) -> 0 | I7: 0 | J7: =+Table1[[#This Row],[PHYSICAL]]-Table1[[#This Row],[THEORETICAL]] -> 0 | K7: =+Table1[[#This Row],[RECEIPTS]] -> 0 | L7: =+Table1[[#This Row],[RETURNS]] -> 0 | M7: =+Table1[[#This Row],[EXCHANGED]] -> 0 | N7: =+Table1[[#This Row],[SALES]] -> 0 | O7: =+Table1[[#This Row],[ISSUES]] -> 0 | P7: =Table1[[#This Row],[RECEIPTS TO]]/1 -> 0 | Q7: =+Table1[[#This Row],[RETURNS ]]/1 -> 0 | R7: =+Table1[[#This Row],[EXCHANGED TO]]/1 -> 0 | S7: =+Table1[[#This Row],[SALES TO]]/1 -> 0 | T7: =+Table1[[#This Row],[ISSUES TO]]/1 -> 0 | U7: =IFERROR(+H7/(P7+Q7+R7+S7+T7),0) -> 0
A8: 110*12 PET BOPP | B8: 8.5 | C8: 0 | D8: 0 | E8: 0 | F8: 0 | G8: 0 | H8: =+(Table1[[#This Row],[OPENING ]]+Table1[[#This Row],[RECEIPTS]]+Table1[[#This Row],[RETURNS]])-(Table1[[#This Row],[ISSUES]]+Table1[[#This Row],[EXCHANGED]]+Table1[[#This Row],[SALES]]) -> 8.5 | I8: 8.5 | J8: =+Table1[[#This Row],[PHYSICAL]]-Table1[[#This Row],[THEORETICAL]] -> 0 | K8: =+Table1[[#This Row],[RECEIPTS]] -> 0 | L8: =+Table1[[#This Row],[RETURNS]] -> 0 | M8: =+Table1[[#This Row],[EXCHANGED]] -> 0 | N8: =+Table1[[#This Row],[SALES]] -> 0 | O8: =+Table1[[#This Row],[ISSUES]] -> 0 | P8: =Table1[[#This Row],[RECEIPTS TO]]/1 -> 0 | Q8: =+Table1[[#This Row],[RETURNS ]]/1 -> 0 | R8: =+Table1[[#This Row],[EXCHANGED TO]]/1 -> 0 | S8: =+Table1[[#This Row],[SALES TO]]/1 -> 0 | T8: =+Table1[[#This Row],[ISSUES TO]]/1 -> 0 | U8: =IFERROR(+H8/(P8+Q8+R8+S8+T8),0) -> 0
A9: 115*12 PET BOPP | B9: 15 | C9: 0 | D9: 0 | E9: 0 | F9: 0 | G9: 0 | H9: =+(Table1[[#This Row],[OPENING ]]+Table1[[#This Row],[RECEIPTS]]+Table1[[#This Row],[RETURNS]])-(Table1[[#This Row],[ISSUES]]+Table1[[#This Row],[EXCHANGED]]+Table1[[#This Row],[SALES]]) -> 15 | I9: 15 | J9: =+Table1[[#This Row],[PHYSICAL]]-Table1[[#This Row],[THEORETICAL]] -> 0 | K9: =+Table1[[#This Row],[RECEIPTS]] -> 0 | L9: =+Table1[[#This Row],[RETURNS]] -> 0 | M9: =+Table1[[#This Row],[EXCHANGED]] -> 0 | N9: =+Table1[[#This Row],[SALES]] -> 0 | O9: =+Table1[[#This Row],[ISSUES]] -> 0 | P9: =Table1[[#This Row],[RECEIPTS TO]]/1 -> 0 | Q9: =+Table1[[#This Row],[RETURNS ]]/1 -> 0 | R9: =+Table1[[#This Row],[EXCHANGED TO]]/1 -> 0 | S9: =+Table1[[#This Row],[SALES TO]]/1 -> 0 | T9: =+Table1[[#This Row],[ISSUES TO]]/1 -> 0 | U9: =IFERROR(+H9/(P9+Q9+R9+S9+T9),0) -> 0
A10: 125*12 PET BOPP | B10: 18 | C10: 0 | D10: 0 | E10: 0 | F10: 0 | G10: 0 | H10: =+(Table1[[#This Row],[OPENING ]]+Table1[[#This Row],[RECEIPTS]]+Table1[[#This Row],[RETURNS]])-(Table1[[#This Row],[ISSUES]]+Table1[[#This Row],[EXCHANGED]]+Table1[[#This Row],[SALES]]) -> 18 | I10: 18 | J10: =+Table1[[#This Row],[PHYSICAL]]-Table1[[#This Row],[THEORETICAL]] -> 0 | K10: =+Table1[[#This Row],[RECEIPTS]] -> 0 | L10: =+Table1[[#This Row],[RETURNS]] -> 0 | M10: =+Table1[[#This Row],[EXCHANGED]] -> 0 | N10: =+Table1[[#This Row],[SALES]] -> 0 | O10: =+Table1[[#This Row],[ISSUES]] -> 0 | P10: =Table1[[#This Row],[RECEIPTS TO]]/1 -> 0 | Q10: =+Table1[[#This Row],[RETURNS ]]/1 -> 0 | R10: =+Table1[[#This Row],[EXCHANGED TO]]/1 -> 0 | S10: =+Table1[[#This Row],[SALES TO]]/1 -> 0 | T10: =+Table1[[#This Row],[ISSUES TO]]/1 -> 0 | U10: =IFERROR(+H10/(P10+Q10+R10+S10+T10),0) -> 0
A11: 129*12 PET BOPP | B11: 10 | C11: 0 | D11: 0 | E11: 0 | F11: 0 | G11: 0 | H11: =+(Table1[[#This Row],[OPENING ]]+Table1[[#This Row],[RECEIPTS]]+Table1[[#This Row],[RETURNS]])-(Table1[[#This Row],[ISSUES]]+Table1[[#This Row],[EXCHANGED]]+Table1[[#This Row],[SALES]]) -> 10 | I11: 10 | J11: =+Table1[[#This Row],[PHYSICAL]]-Table1[[#This Row],[THEORETICAL]] -> 0 | K11: =+Table1[[#This Row],[RECEIPTS]] -> 0 | L11: =+Table1[[#This Row],[RETURNS]] -> 0 | M11: =+Table1[[#This Row],[EXCHANGED]] -> 0 | N11: =+Table1[[#This Row],[SALES]] -> 0 | O11: =+Table1[[#This Row],[ISSUES]] -> 0 | P11: =Table1[[#This Row],[RECEIPTS TO]]/1 -> 0 | Q11: =+Table1[[#This Row],[RETURNS ]]/1 -> 0 | R11: =+Table1[[#This Row],[EXCHANGED TO]]/1 -> 0 | S11: =+Table1[[#This Row],[SALES TO]]/1 -> 0 | T11: =+Table1[[#This Row],[ISSUES TO]]/1 -> 0 | U11: =IFERROR(+H11/(P11+Q11+R11+S11+T11),0) -> 0
A12: 150*12 PET BOPP | B12: 28.6 | C12: 0 | D12: 0 | E12: 0 | F12: 0 | G12: 0 | H12: =+(Table1[[#This Row],[OPENING ]]+Table1[[#This Row],[RECEIPTS]]+Table1[[#This Row],[RETURNS]])-(Table1[[#This Row],[ISSUES]]+Table1[[#This Row],[EXCHANGED]]+Table1[[#This Row],[SALES]]) -> 28.6 | I12: 28.6 | J12: =+Table1[[#This Row],[PHYSICAL]]-Table1[[#This Row],[THEORETICAL]] -> 0 | K12: =+Table1[[#This Row],[RECEIPTS]] -> 0 | L12: =+Table1[[#This Row],[RETURNS]] -> 0 | M12: =+Table1[[#This Row],[EXCHANGED]] -> 0 | N12: =+Table1[[#This Row],[SALES]] -> 0 | O12: =+Table1[[#This Row],[ISSUES]] -> 0 | P12: =Table1[[#This Row],[RECEIPTS TO]]/1 -> 0 | Q12: =+Table1[[#This Row],[RETURNS ]]/1 -> 0 | R12: =+Table1[[#This Row],[EXCHANGED TO]]/1 -> 0 | S12: =+Table1[[#This Row],[SALES TO]]/1 -> 0 | T12: =+Table1[[#This Row],[ISSUES TO]]/1 -> 0 | U12: =IFERROR(+H12/(P12+Q12+R12+S12+T12),0) -> 0
A13: 155*12 PET BOPP | B13: 23.5 | C13: 0 | D13: 0 | E13: 0 | F13: 0 | G13: 0 | H13: =+(Table1[[#This Row],[OPENING ]]+Table1[[#This Row],[RECEIPTS]]+Table1[[#This Row],[RETURNS]])-(Table1[[#This Row],[ISSUES]]+Table1[[#This Row],[EXCHANGED]]+Table1[[#This Row],[SALES]]) -> 23.5 | I13: 23.5 | J13: =+Table1[[#This Row],[PHYSICAL]]-Table1[[#This Row],[THEORETICAL]] -> 0 | K13: =+Table1[[#This Row],[RECEIPTS]] -> 0 | L13: =+Table1[[#This Row],[RETURNS]] -> 0 | M13: =+Table1[[#This Row],[EXCHANGED]] -> 0 | N13: =+Table1[[#This Row],[SALES]] -> 0 | O13: =+Table1[[#This Row],[ISSUES]] -> 0 | P13: =Table1[[#This Row],[RECEIPTS TO]]/1 -> 0 | Q13: =+Table1[[#This Row],[RETURNS ]]/1 -> 0 | R13: =+Table1[[#This Row],[EXCHANGED TO]]/1 -> 0 | S13: =+Table1[[#This Row],[SALES TO]]/1 -> 0 | T13: =+Table1[[#This Row],[ISSUES TO]]/1 -> 0 | U13: =IFERROR(+H13/(P13+Q13+R13+S13+T13),0) -> 0
A14: 160*12 PET BOPP | B14: 30.5 | C14: 0 | D14: 0 | E14: 0 | F14: 0 | G14: 0 | H14: =+(Table1[[#This Row],[OPENING ]]+Table1[[#This Row],[RECEIPTS]]+Table1[[#This Row],[RETURNS]])-(Table1[[#This Row],[ISSUES]]+Table1[[#This Row],[EXCHANGED]]+Table1[[#This Row],[SALES]]) -> 30.5 | I14: 30.5 | J14: =+Table1[[#This Row],[PHYSICAL]]-Table1[[#This Row],[THEORETICAL]] -> 0 | K14: =+Table1[[#This Row],[RECEIPTS]] -> 0 | L14: =+Table1[[#This Row],[RETURNS]] -> 0 | M14: =+Table1[[#This Row],[EXCHANGED]] -> 0 | N14: =+Table1[[#This Row],[SALES]] -> 0 | O14: =+Table1[[#This Row],[ISSUES]] -> 0 | P14: =Table1[[#This Row],[RECEIPTS TO]]/1 -> 0 | Q14: =+Table1[[#This Row],[RETURNS ]]/1 -> 0 | R14: =+Table1[[#This Row],[EXCHANGED TO]]/1 -> 0 | S14: =+Table1[[#This Row],[SALES TO]]/1 -> 0 | T14: =+Table1[[#This Row],[ISSUES TO]]/1 -> 0 | U14: =IFERROR(+H14/(P14+Q14+R14+S14+T14),0) -> 0
A15: 165*12 PET BOPP | B15: 33.5 | C15: 0 | D15: 0 | E15: 0 | F15: 0 | G15: 0 | H15: =+(Table1[[#This Row],[OPENING ]]+Table1[[#This Row],[RECEIPTS]]+Table1[[#This Row],[RETURNS]])-(Table1[[#This Row],[ISSUES]]+Table1[[#This Row],[EXCHANGED]]+Table1[[#This Row],[SALES]]) -> 33.5 | I15: 33.5 | J15: =+Table1[[#This Row],[PHYSICAL]]-Table1[[#This Row],[THEORETICAL]] -> 0 | K15: =+Table1[[#This Row],[RECEIPTS]] -> 0 | L15: =+Table1[[#This Row],[RETURNS]] -> 0 | M15: =+Table1[[#This Row],[EXCHANGED]] -> 0 | N15: =+Table1[[#This Row],[SALES]] -> 0 | O15: =+Table1[[#This Row],[ISSUES]] -> 0 | P15: =Table1[[#This Row],[RECEIPTS TO]]/1 -> 0 | Q15: =+Table1[[#This Row],[RETURNS ]]/1 -> 0 | R15: =+Table1[[#This Row],[EXCHANGED TO]]/1 -> 0 | S15: =+Table1[[#This Row],[SALES TO]]/1 -> 0 | T15: =+Table1[[#This Row],[ISSUES TO]]/1 -> 0 | U15: =IFERROR(+H15/(P15+Q15+R15+S15+T15),0) -> 0
A16: 218*12 PET BOPP | B16: 36 | C16: 0 | D16: 0 | E16: 0 | F16: 0 | G16: 0 | H16: =+(Table1[[#This Row],[OPENING ]]+Table1[[#This Row],[RECEIPTS]]+Table1[[#This Row],[RETURNS]])-(Table1[[#This Row],[ISSUES]]+Table1[[#This Row],[EXCHANGED]]+Table1[[#This Row],[SALES]]) -> 36 | I16: 36 | J16: =+Table1[[#This Row],[PHYSICAL]]-Table1[[#This Row],[THEORETICAL]] -> 0 | K16: =+Table1[[#This Row],[RECEIPTS]] -> 0 | L16: =+Table1[[#This Row],[RETURNS]] -> 0 | M16: =+Table1[[#This Row],[EXCHANGED]] -> 0 | N16: =+Table1[[#This Row],[SALES]] -> 0 | O16: =+Table1[[#This Row],[ISSUES]] -> 0 | P16: =Table1[[#This Row],[RECEIPTS TO]]/1 -> 0 | Q16: =+Table1[[#This Row],[RETURNS ]]/1 -> 0 | R16: =+Table1[[#This Row],[EXCHANGED TO]]/1 -> 0 | S16: =+Table1[[#This Row],[SALES TO]]/1 -> 0 | T16: =+Table1[[#This Row],[ISSUES TO]]/1 -> 0 | U16: =IFERROR(+H16/(P16+Q16+R16+S16+T16),0) -> 0
A17: 220*12 PET BOPP | B17: 0 | C17: 0 | D17: 0 | E17: 0 | F17: 0 | G17: 0 | H17: =+(Table1[[#This Row],[OPENING ]]+Table1[[#This Row],[RECEIPTS]]+Table1[[#This Row],[RETURNS]])-(Table1[[#This Row],[ISSUES]]+Table1[[#This Row],[EXCHANGED]]+Table1[[#This Row],[SALES]]) -> 0 | J17: =+Table1[[#This Row],[PHYSICAL]]-Table1[[#This Row],[THEORETICAL]] -> 0 | K17: =+Table1[[#This Row],[RECEIPTS]] -> 0 | L17: =+Table1[[#This Row],[RETURNS]] -> 0 | M17: =+Table1[[#This Row],[EXCHANGED]] -> 0 | N17: =+Table1[[#This Row],[SALES]] -> 0 | O17: =+Table1[[#This Row],[ISSUES]] -> 0 | P17: =Table1[[#This Row],[RECEIPTS TO]]/1 -> 0 | Q17: =+Table1[[#This Row],[RETURNS ]]/1 -> 0 | R17: =+Table1[[#This Row],[EXCHANGED TO]]/1 -> 0 | S17: =+Table1[[#This Row],[SALES TO]]/1 -> 0 | T17: =+Table1[[#This Row],[ISSUES TO]]/1 -> 0 | U17: =IFERROR(+H17/(P17+Q17+R17+S17+T17),0) -> 0
A18: 229*12 PET BOPP | B18: 0 | C18: 0 | D18: 0 | E18: 0 | F18: 0 | G18: 0 | H18: =+(Table1[[#This Row],[OPENING ]]+Table1[[#This Row],[RECEIPTS]]+Table1[[#This Row],[RETURNS]])-(Table1[[#This Row],[ISSUES]]+Table1[[#This Row],[EXCHANGED]]+Table1[[#This Row],[SALES]]) -> 0 | J18: =+Table1[[#This Row],[PHYSICAL]]-Table1[[#This Row],[THEORETICAL]] -> 0 | K18: =+Table1[[#This Row],[RECEIPTS]] -> 0 | L18: =+Table1[[#This Row],[RETURNS]] -> 0 | M18: =+Table1[[#This Row],[EXCHANGED]] -> 0 | N18: =+Table1[[#This Row],[SALES]] -> 0 | O18: =+Table1[[#This Row],[ISSUES]] -> 0 | P18: =Table1[[#This Row],[RECEIPTS TO]]/1 -> 0 | Q18: =+Table1[[#This Row],[RETURNS ]]/1 -> 0 | R18: =+Table1[[#This Row],[EXCHANGED TO]]/1 -> 0 | S18: =+Table1[[#This Row],[SALES TO]]/1 -> 0 | T18: =+Table1[[#This Row],[ISSUES TO]]/1 -> 0 | U18: =IFERROR(+H18/(P18+Q18+R18+S18+T18),0) -> 0
A19: 230*19 PET BOPP | B19: 27 | C19: 0 | D19: 0 | E19: 0 | F19: 0 | G19: 0 | H19: =+(Table1[[#This Row],[OPENING ]]+Table1[[#This Row],[RECEIPTS]]+Table1[[#This Row],[RETURNS]])-(Table1[[#This Row],[ISSUES]]+Table1[[#This Row],[EXCHANGED]]+Table1[[#This Row],[SALES]]) -> 27 | I19: 27 | J19: =+Table1[[#This Row],[PHYSICAL]]-Table1[[#This Row],[THEORETICAL]] -> 0 | K19: =+Table1[[#This Row],[RECEIPTS]] -> 0 | L19: =+Table1[[#This Row],[RETURNS]] -> 0 | M19: =+Table1[[#This Row],[EXCHANGED]] -> 0 | N19: =+Table1[[#This Row],[SALES]] -> 0 | O19: =+Table1[[#This Row],[ISSUES]] -> 0 | P19: =Table1[[#This Row],[RECEIPTS TO]]/1 -> 0 | Q19: =+Table1[[#This Row],[RETURNS ]]/1 -> 0 | R19: =+Table1[[#This Row],[EXCHANGED TO]]/1 -> 0 | S19: =+Table1[[#This Row],[SALES TO]]/1 -> 0 | T19: =+Table1[[#This Row],[ISSUES TO]]/1 -> 0 | U19: =IFERROR(+H19/(P19+Q19+R19+S19+T19),0) -> 0
A20: 190*12 PET BOPP | B20: 228.5 | C20: 0 | D20: 0 | E20: 0 | F20: 0 | G20: 0 | H20: =+(Table1[[#This Row],[OPENING ]]+Table1[[#This Row],[RECEIPTS]]+Table1[[#This Row],[RETURNS]])-(Table1[[#This Row],[ISSUES]]+Table1[[#This Row],[EXCHANGED]]+Table1[[#This Row],[SALES]]) -> 228.5 | I20: 228.5 | J20: =+Table1[[#This Row],[PHYSICAL]]-Table1[[#This Row],[THEORETICAL]] -> 0 | K20: =+Table1[[#This Row],[RECEIPTS]] -> 0 | L20: =+Table1[[#This Row],[RETURNS]] -> 0 | M20: =+Table1[[#This Row],[EXCHANGED]] -> 0 | N20: =+Table1[[#This Row],[SALES]] -> 0 | O20: =+Table1[[#This Row],[ISSUES]] -> 0 | P20: =Table1[[#This Row],[RECEIPTS TO]]/1 -> 0 | Q20: =+Table1[[#This Row],[RETURNS ]]/1 -> 0 | R20: =+Table1[[#This Row],[EXCHANGED TO]]/1 -> 0 | S20: =+Table1[[#This Row],[SALES TO]]/1 -> 0 | T20: =+Table1[[#This Row],[ISSUES TO]]/1 -> 0 | U20: =IFERROR(+H20/(P20+Q20+R20+S20+T20),0) -> 0
A21: 170 *12 PET BOPP | B21: 70 | C21: 0 | D21: 0 | E21: 0 | F21: 0 | G21: 0 | H21: =+(Table1[[#This Row],[OPENING ]]+Table1[[#This Row],[RECEIPTS]]+Table1[[#This Row],[RETURNS]])-(Table1[[#This Row],[ISSUES]]+Table1[[#This Row],[EXCHANGED]]+Table1[[#This Row],[SALES]]) -> 70 | I21: 70 | J21: =+Table1[[#This Row],[PHYSICAL]]-Table1[[#This Row],[THEORETICAL]] -> 0 | K21: =+Table1[[#This Row],[RECEIPTS]] -> 0 | L21: =+Table1[[#This Row],[RETURNS]] -> 0 | M21: =+Table1[[#This Row],[EXCHANGED]] -> 0 | N21: =+Table1[[#This Row],[SALES]] -> 0 | O21: =+Table1[[#This Row],[ISSUES]] -> 0 | P21: =Table1[[#This Row],[RECEIPTS TO]]/1 -> 0 | Q21: =+Table1[[#This Row],[RETURNS ]]/1 -> 0 | R21: =+Table1[[#This Row],[EXCHANGED TO]]/1 -> 0 | S21: =+Table1[[#This Row],[SALES TO]]/1 -> 0 | T21: =+Table1[[#This Row],[ISSUES TO]]/1 -> 0 | U21: =IFERROR(+H21/(P21+Q21+R21+S21+T21),0) -> 0
A22: 140*12 PET BOPP | B22: 14 | C22: 0 | D22: 0 | E22: 0 | F22: 0 | G22: 0 | H22: =+(Table1[[#This Row],[OPENING ]]+Table1[[#This Row],[RECEIPTS]]+Table1[[#This Row],[RETURNS]])-(Table1[[#This Row],[ISSUES]]+Table1[[#This Row],[EXCHANGED]]+Table1[[#This Row],[SALES]]) -> 14 | I22: 14 | J22: =+Table1[[#This Row],[PHYSICAL]]-Table1[[#This Row],[THEORETICAL]] -> 0 | K22: =+Table1[[#This Row],[RECEIPTS]] -> 0 | L22: =+Table1[[#This Row],[RETURNS]] -> 0 | M22: =+Table1[[#This Row],[EXCHANGED]] -> 0 | N22: =+Table1[[#This Row],[SALES]] -> 0 | O22: =+Table1[[#This Row],[ISSUES]] -> 0 | P22: =Table1[[#This Row],[RECEIPTS TO]]/1 -> 0 | Q22: =+Table1[[#This Row],[RETURNS ]]/1 -> 0 | R22: =+Table1[[#This Row],[EXCHANGED TO]]/1 -> 0 | S22: =+Table1[[#This Row],[SALES TO]]/1 -> 0 | T22: =+Table1[[#This Row],[ISSUES TO]]/1 -> 0 | U22: =IFERROR(+H22/(P22+Q22+R22+S22+T22),0) -> 0
A23: 290*12 PET BOPP | B23: 70 | C23: 0 | D23: 0 | E23: 0 | F23: 0 | G23: 0 | H23: =+(Table1[[#This Row],[OPENING ]]+Table1[[#This Row],[RECEIPTS]]+Table1[[#This Row],[RETURNS]])-(Table1[[#This Row],[ISSUES]]+Table1[[#This Row],[EXCHANGED]]+Table1[[#This Row],[SALES]]) -> 70 | I23: 70 | J23: =+Table1[[#This Row],[PHYSICAL]]-Table1[[#This Row],[THEORETICAL]] -> 0 | K23: =+Table1[[#This Row],[RECEIPTS]] -> 0 | L23: =+Table1[[#This Row],[RETURNS]] -> 0 | M23: =+Table1[[#This Row],[EXCHANGED]] -> 0 | N23: =+Table1[[#This Row],[SALES]] -> 0 | O23: =+Table1[[#This Row],[ISSUES]] -> 0 | P23: =Table1[[#This Row],[RECEIPTS TO]]/1 -> 0 | Q23: =+Table1[[#This Row],[RETURNS ]]/1 -> 0 | R23: =+Table1[[#This Row],[EXCHANGED TO]]/1 -> 0 | S23: =+Table1[[#This Row],[SALES TO]]/1 -> 0 | T23: =+Table1[[#This Row],[ISSUES TO]]/1 -> 0 | U23: =IFERROR(+H23/(P23+Q23+R23+S23+T23),0) -> 0
A24: 320*12 PET BOPP | B24: 49 | C24: 0 | D24: 0 | E24: 0 | F24: 0 | G24: 0 | H24: =+(Table1[[#This Row],[OPENING ]]+Table1[[#This Row],[RECEIPTS]]+Table1[[#This Row],[RETURNS]])-(Table1[[#This Row],[ISSUES]]+Table1[[#This Row],[EXCHANGED]]+Table1[[#This Row],[SALES]]) -> 49 | I24: 49 | J24: =+Table1[[#This Row],[PHYSICAL]]-Table1[[#This Row],[THEORETICAL]] -> 0 | K24: =+Table1[[#This Row],[RECEIPTS]] -> 0 | L24: =+Table1[[#This Row],[RETURNS]] -> 0 | M24: =+Table1[[#This Row],[EXCHANGED]] -> 0 | N24: =+Table1[[#This Row],[SALES]] -> 0 | O24: =+Table1[[#This Row],[ISSUES]] -> 0 | P24: =Table1[[#This Row],[RECEIPTS TO]]/1 -> 0 | Q24: =+Table1[[#This Row],[RETURNS ]]/1 -> 0 | R24: =+Table1[[#This Row],[EXCHANGED TO]]/1 -> 0 | S24: =+Table1[[#This Row],[SALES TO]]/1 -> 0 | T24: =+Table1[[#This Row],[ISSUES TO]]/1 -> 0 | U24: =IFERROR(+H24/(P24+Q24+R24+S24+T24),0) -> 0
B25: 0 | C25: 0 | D25: 0 | E25: 0 | F25: 0 | G25: 0 | H25: =+(Table1[[#This Row],[OPENING ]]+Table1[[#This Row],[RECEIPTS]]+Table1[[#This Row],[RETURNS]])-(Table1[[#This Row],[ISSUES]]+Table1[[#This Row],[EXCHANGED]]+Table1[[#This Row],[SALES]]) -> 0 | J25: =+Table1[[#This Row],[PHYSICAL]]-Table1[[#This Row],[THEORETICAL]] -> 0 | K25: =+Table1[[#This Row],[RECEIPTS]] -> 0 | L25: =+Table1[[#This Row],[RETURNS]] -> 0 | M25: =+Table1[[#This Row],[EXCHANGED]] -> 0 | N25: =+Table1[[#This Row],[SALES]] -> 0 | O25: =+Table1[[#This Row],[ISSUES]] -> 0 | P25: =Table1[[#This Row],[RECEIPTS TO]]/1 -> 0 | Q25: =+Table1[[#This Row],[RETURNS ]]/1 -> 0 | R25: =+Table1[[#This Row],[EXCHANGED TO]]/1 -> 0 | S25: =+Table1[[#This Row],[SALES TO]]/1 -> 0 | T25: =+Table1[[#This Row],[ISSUES TO]]/1 -> 0 | U25: =IFERROR(+H25/(P25+Q25+R25+S25+T25),0) -> 0
A26: CLEAR BOPP | B26: 0 | C26: 0 | D26: 0 | E26: 0 | F26: 0 | G26: 0 | H26: =+(Table1[[#This Row],[OPENING ]]+Table1[[#This Row],[RECEIPTS]]+Table1[[#This Row],[RETURNS]])-(Table1[[#This Row],[ISSUES]]+Table1[[#This Row],[EXCHANGED]]+Table1[[#This Row],[SALES]]) -> 0 | J26: =+Table1[[#This Row],[PHYSICAL]]-Table1[[#This Row],[THEORETICAL]] -> 0 | K26: =+Table1[[#This Row],[RECEIPTS]] -> 0 | L26: =+Table1[[#This Row],[RETURNS]] -> 0 | M26: =+Table1[[#This Row],[EXCHANGED]] -> 0 | N26: =+Table1[[#This Row],[SALES]] -> 0 | O26: =+Table1[[#This Row],[ISSUES]] -> 0 | P26: =Table1[[#This Row],[RECEIPTS TO]]/1 -> 0 | Q26: =+Table1[[#This Row],[RETURNS ]]/1 -> 0 | R26: =+Table1[[#This Row],[EXCHANGED TO]]/1 -> 0 | S26: =+Table1[[#This Row],[SALES TO]]/1 -> 0 | T26: =+Table1[[#This Row],[ISSUES TO]]/1 -> 0 | U26: =IFERROR(+H26/(P26+Q26+R26+S26+T26),0) -> 0
A27: 755*18 CLEAR BOPP | B27: 506.2 | C27: 0 | D27: 0 | E27: 0 | F27: 0 | G27: 0 | H27: =+(Table1[[#This Row],[OPENING ]]+Table1[[#This Row],[RECEIPTS]]+Table1[[#This Row],[RETURNS]])-(Table1[[#This Row],[ISSUES]]+Table1[[#This Row],[EXCHANGED]]+Table1[[#This Row],[SALES]]) -> 506.2 | I27: 506.2 | J27: =+Table1[[#This Row],[PHYSICAL]]-Table1[[#This Row],[THEORETICAL]] -> 0 | U27: =IFERROR(+H27/(P27+Q27+R27+S27+T27),0) -> 0
A28: 300 MM X 20 UM COOL CYCLONE | B28: 0 | C28: 0 | D28: 0 | E28: 0 | F28: 0 | G28: 0 | H28: =+(Table1[[#This Row],[OPENING ]]+Table1[[#This Row],[RECEIPTS]]+Table1[[#This Row],[RETURNS]])-(Table1[[#This Row],[ISSUES]]+Table1[[#This Row],[EXCHANGED]]+Table1[[#This Row],[SALES]]) -> 0 | J28: =+Table1[[#This Row],[PHYSICAL]]-Table1[[#This Row],[THEORETICAL]] -> 0 | U28: =IFERROR(+H28/(P28+Q28+R28+S28+T28),0) -> 0
A29: 570 MM X 20 UM COOL CYCLONE | B29: 318.3 | C29: 0 | D29: 0 | E29: 0 | F29: 0 | G29: 0 | H29: =+(Table1[[#This Row],[OPENING ]]+Table1[[#This Row],[RECEIPTS]]+Table1[[#This Row],[RETURNS]])-(Table1[[#This Row],[ISSUES]]+Table1[[#This Row],[EXCHANGED]]+Table1[[#This Row],[SALES]]) -> 318.3 | I29: 318.3 | J29: =+Table1[[#This Row],[PHYSICAL]]-Table1[[#This Row],[THEORETICAL]] -> 0 | U29: =IFERROR(+H29/(P29+Q29+R29+S29+T29),0) -> 0
A30: 550 MM X 20 UM COOL CYCLONE | B30: 0 | C30: 0 | D30: 0 | E30: 0 | F30: 0 | G30: 0 | H30: =+(Table1[[#This Row],[OPENING ]]+Table1[[#This Row],[RECEIPTS]]+Table1[[#This Row],[RETURNS]])-(Table1[[#This Row],[ISSUES]]+Table1[[#This Row],[EXCHANGED]]+Table1[[#This Row],[SALES]]) -> 0 | I30: 0 | J30: =+Table1[[#This Row],[PHYSICAL]]-Table1[[#This Row],[THEORETICAL]] -> 0 | U30: =IFERROR(+H30/(P30+Q30+R30+S30+T30),0) -> 0
A31: 1100 MM X 30 UM COOL CYCLONE | B31: 0 | C31: 0 | D31: 0 | E31: 0 | F31: 0 | G31: 0 | H31: =+(Table1[[#This Row],[OPENING ]]+Table1[[#This Row],[RECEIPTS]]+Table1[[#This Row],[RETURNS]])-(Table1[[#This Row],[ISSUES]]+Table1[[#This Row],[EXCHANGED]]+Table1[[#This Row],[SALES]]) -> 0 | J31: =+Table1[[#This Row],[PHYSICAL]]-Table1[[#This Row],[THEORETICAL]] -> 0 | U31: =IFERROR(+H31/(P31+Q31+R31+S31+T31),0) -> 0
A32: 1100 MM X 30 UM SRF | B32: 0 | C32: 0 | D32: 0 | E32: 0 | F32: 0 | G32: 0 | H32: =+(Table1[[#This Row],[OPENING ]]+Table1[[#This Row],[RECEIPTS]]+Table1[[#This Row],[RETURNS]])-(Table1[[#This Row],[ISSUES]]+Table1[[#This Row],[EXCHANGED]]+Table1[[#This Row],[SALES]]) -> 0 | J32: =+Table1[[#This Row],[PHYSICAL]]-Table1[[#This Row],[THEORETICAL]] -> 0 | U32: =IFERROR(+H32/(P32+Q32+R32+S32+T32),0) -> 0
A33: 390 MM X 20 UM | B33: 0 | C33: 0 | D33: 0 | E33: 0 | F33: 0 | G33: 0 | H33: =+(Table1[[#This Row],[OPENING ]]+Table1[[#This Row],[RECEIPTS]]+Table1[[#This Row],[RETURNS]])-(Table1[[#This Row],[ISSUES]]+Table1[[#This Row],[EXCHANGED]]+Table1[[#This Row],[SALES]]) -> 0 | J33: =+Table1[[#This Row],[PHYSICAL]]-Table1[[#This Row],[THEORETICAL]] -> 0 | U33: =IFERROR(+H33/(P33+Q33+R33+S33+T33),0) -> 0
A34: 550 MM X 30UM | B34: 58.1 | C34: 0 | D34: 0 | E34: 0 | F34: 0 | G34: 0 | H34: =+(Table1[[#This Row],[OPENING ]]+Table1[[#This Row],[RECEIPTS]]+Table1[[#This Row],[RETURNS]])-(Table1[[#This Row],[ISSUES]]+Table1[[#This Row],[EXCHANGED]]+Table1[[#This Row],[SALES]]) -> 58.1 | I34: 58.1 | J34: =+Table1[[#This Row],[PHYSICAL]]-Table1[[#This Row],[THEORETICAL]] -> 0 | U34: =IFERROR(+H34/(P34+Q34+R34+S34+T34),0) -> 0
A35: 400 MM X 30 UM | B35: 0 | C35: 0 | D35: 0 | E35: 0 | F35: 0 | G35: 0 | H35: =+(Table1[[#This Row],[OPENING ]]+Table1[[#This Row],[RECEIPTS]]+Table1[[#This Row],[RETURNS]])-(Table1[[#This Row],[ISSUES]]+Table1[[#This Row],[EXCHANGED]]+Table1[[#This Row],[SALES]]) -> 0 | J35: =+Table1[[#This Row],[PHYSICAL]]-Table1[[#This Row],[THEORETICAL]] -> 0 | U35: =IFERROR(+H35/(P35+Q35+R35+S35+T35),0) -> 0
A36: 640 MM X 20 UM | B36: 31.35 | C36: 0 | D36: 0 | E36: 0 | F36: 0 | G36: 0 | H36: =+(Table1[[#This Row],[OPENING ]]+Table1[[#This Row],[RECEIPTS]]+Table1[[#This Row],[RETURNS]])-(Table1[[#This Row],[ISSUES]]+Table1[[#This Row],[EXCHANGED]]+Table1[[#This Row],[SALES]]) -> 31.35 | I36: 31.35 | J36: =+Table1[[#This Row],[PHYSICAL]]-Table1[[#This Row],[THEORETICAL]] -> 0 | U36: =IFERROR(+H36/(P36+Q36+R36+S36+T36),0) -> 0
A37: 400 MM x 20 UM COOL CYCLONE | B37: 0 | C37: 0 | D37: 0 | E37: 0 | F37: 0 | G37: 0 | H37: =+(Table1[[#This Row],[OPENING ]]+Table1[[#This Row],[RECEIPTS]]+Table1[[#This Row],[RETURNS]])-(Table1[[#This Row],[ISSUES]]+Table1[[#This Row],[EXCHANGED]]+Table1[[#This Row],[SALES]]) -> 0 | J37: =+Table1[[#This Row],[PHYSICAL]]-Table1[[#This Row],[THEORETICAL]] -> 0 | U37: =IFERROR(+H37/(P37+Q37+R37+S37+T37),0) -> 0
A38: TOTAL BOPP | B38: =SUM(B5:B37) -> 1576.05 | C38: =SUM(C5:C37) -> 0 | D38: =SUM(D5:D37) -> 0 | E38: =SUM(E5:E37) -> 0 | F38: =SUM(F5:F37) -> 0 | G38: =SUM(G5:G37) -> 0 | H38: =SUM(H5:H37) -> 1576.05 | I38: =SUM(I5:I37) -> 1576.05 | ... U38: =SUM(U5:U37) -> 0
A39: TAEJIN BOPP
A40: HEAT SEALABLE CLEAR BOPP FILM TREATED OUTSIDE
...

Sheet DAY2
A1: BOPP STOCK MOVEMENT REPORT AS OF 31/8/26
A2: DESCRIPTION AND CODE | B2: OPENING | C2: RECEIPTS | D2: RETURNS | E2: EXCHANGED | F2: SALES | G2: ISSUES | H2: THEORETICAL | I2: PHYSICAL | J2: R/MATERIAL | K2: RECEIPTS TO | L2: RETURNS | M2: EXCHANGED TO | N2: SALES TO | O2: ISSUES TO | P2: AVE RECEIPTS | Q2: AVE RETURNS | R2: AVE EXCHANGED | S2: AVE SALES | T2: AVE ISSUES | U2: STOCK DAYS
B3: STOCK | H3: CLOSING STOCK | I3: CLOSING STOCK | K3: DATE | L3: TO DATE | M3: DATE | N3: DATE | O3: DATE | P3: PER DAY | Q3: PER DAY | R3: PER DAY | S3: PER DAY | T3: PER DAY
A4: BOPP : CLEAR & PET
B5: ='DAY1'!H5 -> 0 | C5: 0 | D5: 0 | E5: 0 | F5: 0 | G5: 0 | H5: =+(Table14[[#This Row],[OPENING ]]+Table14[[#This Row],[RECEIPTS]]+Table14[[#This Row],[RETURNS]])-(Table14[[#This Row],[ISSUES]]+Table14[[#This Row],[EXCHANGED]]+Table14[[#This Row],[SALES]]) -> 0 | J5: =+I5-H5 -> 0 | K5: =+'DAY1'!K5+'DAY2'!C5 -> 0 | L5: =+'DAY1'!L5+'DAY2'!D5 -> 0 | M5: =+'DAY1'!M5+'DAY2'!E5 -> 0 | N5: =+'DAY1'!N5+'DAY2'!F5 -> 0 | O5: =+'DAY1'!O5+'DAY2'!G5 -> 0 | P5: =+Table14[[#This Row],[RECEIPTS TO]]/1 -> 0 | Q5: =+Table14[[#This Row],[RETURNS ]]/1 -> 0 | R5: =+Table14[[#This Row],[EXCHANGED TO]]/1 -> 0 | S5: =+Table14[[#This Row],[SALES TO]]/1 -> 0 | T5: =+Table14[[#This Row],[ISSUES TO]]/1 -> 0 | U5: =IFERROR(+H5/(P5+Q5+R5+S5+T5),0) -> 0
B6: ='DAY1'!H6 -> 0 | C6: 0 | D6: 0 | E6: 0 | F6: 0 | G6: 0 | H6: =+(Table14[[#This Row],[OPENING ]]+Table14[[#This Row],[RECEIPTS]]+Table14[[#This Row],[RETURNS]])-(Table14[[#This Row],[ISSUES]]+Table14[[#This Row],[EXCHANGED]]+Table14[[#This Row],[SALES]]) -> 0 | J6: =+I6-H6 -> 0 | K6: =+'DAY1'!K6+'DAY2'!C6 -> 0 | L6: =+'DAY1'!L6+'DAY2'!D6 -> 0 | M6: =+'DAY1'!M6+'DAY2'!E6 -> 0 | N6: =+'DAY1'!N6+'DAY2'!F6 -> 0 | O6: =+'DAY1'!O6+'DAY2'!G6 -> 0 | P6: =+Table14[[#This Row],[RECEIPTS TO]]/1 -> 0 | Q6: =+Table14[[#This Row],[RETURNS ]]/1 -> 0 | R6: =+Table14[[#This Row],[EXCHANGED TO]]/1 -> 0 | S6: =+Table14[[#This Row],[SALES TO]]/1 -> 0 | T6: =+Table14[[#This Row],[ISSUES TO]]/1 -> 0 | U6: =IFERROR(+H6/(P6+Q6+R6+S6+T6),0) -> 0
B7: ='DAY1'!H7 -> 0 | C7: 0 | D7: 0 | E7: 0 | F7: 0 | G7: 0 | H7: =+(Table14[[#This Row],[OPENING ]]+Table14[[#This Row],[RECEIPTS]]+Table14[[#This Row],[RETURNS]])-(Table14[[#This Row],[ISSUES]]+Table14[[#This Row],[EXCHANGED]]+Table14[[#This Row],[SALES]]) -> 0 | J7: =+I7-H7 -> 0 | K7: =+'DAY1'!K7+'DAY2'!C7 -> 0 | L7: =+'DAY1'!L7+'DAY2'!D7 -> 0 | M7: =+'DAY1'!M7+'DAY2'!E7 -> 0 | N7: =+'DAY1'!N7+'DAY2'!F7 -> 0 | O7: =+'DAY1'!O7+'DAY2'!G7 -> 0 | P7: =+Table14[[#This Row],[RECEIPTS TO]]/1 -> 0 | Q7: =+Table14[[#This Row],[RETURNS ]]/1 -> 0 | R7: =+Table14[[#This Row],[EXCHANGED TO]]/1 -> 0 | S7: =+Table14[[#This Row],[SALES TO]]/1 -> 0 | T7: =+Table14[[#This Row],[ISSUES TO]]/1 -> 0 | U7: =IFERROR(+H7/(P7+Q7+R7+S7+T7),0) -> 0
A8: 110*12 PET BOPP | B8: ='DAY1'!H8 -> 8.5 | C8: 0 | D8: 0 | E8: 0 | F8: 0 | G8: 0 | H8: =+(Table14[[#This Row],[OPENING ]]+Table14[[#This Row],[RECEIPTS]]+Table14[[#This Row],[RETURNS]])-(Table14[[#This Row],[ISSUES]]+Table14[[#This Row],[EXCHANGED]]+Table14[[#This Row],[SALES]]) -> 8.5 | I8: 8.5 | J8: =+I8-H8 -> 0 | K8: =+'DAY1'!K8+'DAY2'!C8 -> 0 | L8: =+'DAY1'!L8+'DAY2'!D8 -> 0 | M8: =+'DAY1'!M8+'DAY2'!E8 -> 0 | N8: =+'DAY1'!N8+'DAY2'!F8 -> 0 | O8: =+'DAY1'!O8+'DAY2'!G8 -> 0 | P8: =+Table14[[#This Row],[RECEIPTS TO]]/1 -> 0 | Q8: =+Table14[[#This Row],[RETURNS ]]/1 -> 0 | R8: =+Table14[[#This Row],[EXCHANGED TO]]/1 -> 0 | S8: =+Table14[[#This Row],[SALES TO]]/1 -> 0 | T8: =+Table14[[#This Row],[ISSUES TO]]/1 -> 0 | U8: =IFERROR(+H8/(P8+Q8+R8+S8+T8),0) -> 0
A9: 115*12 PET BOPP | B9: ='DAY1'!H9 -> 15 | C9: 0 | D9: 0 | E9: 0 | F9: 0 | G9: 0 | H9: =+(Table14[[#This Row],[OPENING ]]+Table14[[#This Row],[RECEIPTS]]+Table14[[#This Row],[RETURNS]])-(Table14[[#This Row],[ISSUES]]+Table14[[#This Row],[EXCHANGED]]+Table14[[#This Row],[SALES]]) -> 15 | I9: 15 | J9: =+I9-H9 -> 0 | K9: =+'DAY1'!K9+'DAY2'!C9 -> 0 | L9: =+'DAY1'!L9+'DAY2'!D9 -> 0 | M9: =+'DAY1'!M9+'DAY2'!E9 -> 0 | N9: =+'DAY1'!N9+'DAY2'!F9 -> 0 | O9: =+'DAY1'!O9+'DAY2'!G9 -> 0 | P9: =+Table14[[#This Row],[RECEIPTS TO]]/1 -> 0 | Q9: =+Table14[[#This Row],[RETURNS ]]/1 -> 0 | R9: =+Table14[[#This Row],[EXCHANGED TO]]/1 -> 0 | S9: =+Table14[[#This Row],[SALES TO]]/1 -> 0 | T9: =+Table14[[#This Row],[ISSUES TO]]/1 -> 0 | U9: =IFERROR(+H9/(P9+Q9+R9+S9+T9),0) -> 0
A10: 125*12 PET BOPP | B10: ='DAY1'!H10 -> 18 | C10: 0 | D10: 0 | E10: 0 | F10: 0 | G10: 0 | H10: =+(Table14[[#This Row],[OPENING ]]+Table14[[#This Row],[RECEIPTS]]+Table14[[#This Row],[RETURNS]])-(Table14[[#This Row],[ISSUES]]+Table14[[#This Row],[EXCHANGED]]+Table14[[#This Row],[SALES]]) -> 18 | I10: 18 | J10: =+I10-H10 -> 0 | K10: =+'DAY1'!K10+'DAY2'!C10 -> 0 | L10: =+'DAY1'!L10+'DAY2'!D10 -> 0 | M10: =+'DAY1'!M10+'DAY2'!E10 -> 0 | N10: =+'DAY1'!N10+'DAY2'!F10 -> 0 | O10: =+'DAY1'!O10+'DAY2'!G10 -> 0 | P10: =+Table14[[#This Row],[RECEIPTS TO]]/1 -> 0 | Q10: =+Table14[[#This Row],[RETURNS ]]/1 -> 0 | R10: =+Table14[[#This Row],[EXCHANGED TO]]/1 -> 0 | S10: =+Table14[[#This Row],[SALES TO]]/1 -> 0 | T10: =+Table14[[#This Row],[ISSUES TO]]/1 -> 0 | U10: =IFERROR(+H10/(P10+Q10+R10+S10+T10),0) -> 0
A11: 129*12 PET BOPP | B11: ='DAY1'!H11 -> 10 | C11: 0 | D11: 0 | E11: 0 | F11: 0 | G11: 0 | H11: =+(Table14[[#This Row],[OPENING ]]+Table14[[#This Row],[RECEIPTS]]+Table14[[#This Row],[RETURNS]])-(Table14[[#This Row],[ISSUES]]+Table14[[#This Row],[EXCHANGED]]+Table14[[#This Row],[SALES]]) -> 10 | I11: 10 | J11: =+I11-H11 -> 0 | K11: =+'DAY1'!K11+'DAY2'!C11 -> 0 | L11: =+'DAY1'!L11+'DAY2'!D11 -> 0 | M11: =+'DAY1'!M11+'DAY2'!E11 -> 0 | N11: =+'DAY1'!N11+'DAY2'!F11 -> 0 | O11: =+'DAY1'!O11+'DAY2'!G11 -> 0 | P11: =+Table14[[#This Row],[RECEIPTS TO]]/1 -> 0 | Q11: =+Table14[[#This Row],[RETURNS ]]/1 -> 0 | R11: =+Table14[[#This Row],[EXCHANGED TO]]/1 -> 0 | S11: =+Table14[[#This Row],[SALES TO]]/1 -> 0 | T11: =+Table14[[#This Row],[ISSUES TO]]/1 -> 0 | U11: =IFERROR(+H11/(P11+Q11+R11+S11+T11),0) -> 0
A12: 150*12 PET BOPP | B12: ='DAY1'!H12 -> 28.6 | C12: 0 | D12: 0 | E12: 0 | F12: 0 | G12: 0 | H12: =+(Table14[[#This Row],[OPENING ]]+Table14[[#This Row],[RECEIPTS]]+Table14[[#This Row],[RETURNS]])-(Table14[[#This Row],[ISSUES]]+Table14[[#This Row],[EXCHANGED]]+Table14[[#This Row],[SALES]]) -> 28.6 | I12: 28.6 | J12: =+I12-H12 -> 0 | K12: =+'DAY1'!K12+'DAY2'!C12 -> 0 | L12: =+'DAY1'!L12+'DAY2'!D12 -> 0 | M12: =+'DAY1'!M12+'DAY2'!E12 -> 0 | N12: =+'DAY1'!N12+'DAY2'!F12 -> 0 | O12: =+'DAY1'!O12+'DAY2'!G12 -> 0 | P12: =+Table14[[#This Row],[RECEIPTS TO]]/1 -> 0 | Q12: =+Table14[[#This Row],[RETURNS ]]/1 -> 0 | R12: =+Table14[[#This Row],[EXCHANGED TO]]/1 -> 0 | S12: =+Table14[[#This Row],[SALES TO]]/1 -> 0 | T12: =+Table14[[#This Row],[ISSUES TO]]/1 -> 0 | U12: =IFERROR(+H12/(P12+Q12+R12+S12+T12),0) -> 0
A13: 155*12 PET BOPP | B13: ='DAY1'!H13 -> 23.5 | C13: 0 | D13: 0 | E13: 0 | F13: 0 | G13: 0 | H13: =+(Table14[[#This Row],[OPENING ]]+Table14[[#This Row],[RECEIPTS]]+Table14[[#This Row],[RETURNS]])-(Table14[[#This Row],[ISSUES]]+Table14[[#This Row],[EXCHANGED]]+Table14[[#This Row],[SALES]]) -> 23.5 | I13: 23.5 | J13: =+I13-H13 -> 0 | K13: =+'DAY1'!K13+'DAY2'!C13 -> 0 | L13: =+'DAY1'!L13+'DAY2'!D13 -> 0 | M13: =+'DAY1'!M13+'DAY2'!E13 -> 0 | N13: =+'DAY1'!N13+'DAY2'!F13 -> 0 | O13: =+'DAY1'!O13+'DAY2'!G13 -> 0 | P13: =+Table14[[#This Row],[RECEIPTS TO]]/1 -> 0 | Q13: =+Table14[[#This Row],[RETURNS ]]/1 -> 0 | R13: =+Table14[[#This Row],[EXCHANGED TO]]/1 -> 0 | S13: =+Table14[[#This Row],[SALES TO]]/1 -> 0 | T13: =+Table14[[#This Row],[ISSUES TO]]/1 -> 0 | U13: =IFERROR(+H13/(P13+Q13+R13+S13+T13),0) -> 0
A14: 160*12 PET BOPP | B14: ='DAY1'!H14 -> 30.5 | C14: 0 | D14: 0 | E14: 0 | F14: 0 | G14: 0 | H14: =+(Table14[[#This Row],[OPENING ]]+Table14[[#This Row],[RECEIPTS]]+Table14[[#This Row],[RETURNS]])-(Table14[[#This Row],[ISSUES]]+Table14[[#This Row],[EXCHANGED]]+Table14[[#This Row],[SALES]]) -> 30.5 | I14: 30.5 | J14: =+I14-H14 -> 0 | K14: =+'DAY1'!K14+'DAY2'!C14 -> 0 | L14: =+'DAY1'!L14+'DAY2'!D14 -> 0 | M14: =+'DAY1'!M14+'DAY2'!E14 -> 0 | N14: =+'DAY1'!N14+'DAY2'!F14 -> 0 | O14: =+'DAY1'!O14+'DAY2'!G14 -> 0 | P14: =+Table14[[#This Row],[RECEIPTS TO]]/1 -> 0 | Q14: =+Table14[[#This Row],[RETURNS ]]/1 -> 0 | R14: =+Table14[[#This Row],[EXCHANGED TO]]/1 -> 0 | S14: =+Table14[[#This Row],[SALES TO]]/1 -> 0 | T14: =+Table14[[#This Row],[ISSUES TO]]/1 -> 0 | U14: =IFERROR(+H14/(P14+Q14+R14+S14+T14),0) -> 0
A15: 165*12 PET BOPP | B15: ='DAY1'!H15 -> 33.5 | C15: 0 | D15: 0 | E15: 0 | F15: 0 | G15: 0 | H15: =+(Table14[[#This Row],[OPENING ]]+Table14[[#This Row],[RECEIPTS]]+Table14[[#This Row],[RETURNS]])-(Table14[[#This Row],[ISSUES]]+Table14[[#This Row],[EXCHANGED]]+Table14[[#This Row],[SALES]]) -> 33.5 | I15: 33.5 | J15: =+I15-H15 -> 0 | K15: =+'DAY1'!K15+'DAY2'!C15 -> 0 | L15: =+'DAY1'!L15+'DAY2'!D15 -> 0 | M15: =+'DAY1'!M15+'DAY2'!E15 -> 0 | N15: =+'DAY1'!N15+'DAY2'!F15 -> 0 | O15: =+'DAY1'!O15+'DAY2'!G15 -> 0 | P15: =+Table14[[#This Row],[RECEIPTS TO]]/1 -> 0 | Q15: =+Table14[[#This Row],[RETURNS ]]/1 -> 0 | R15: =+Table14[[#This Row],[EXCHANGED TO]]/1 -> 0 | S15: =+Table14[[#This Row],[SALES TO]]/1 -> 0 | T15: =+Table14[[#This Row],[ISSUES TO]]/1 -> 0 | U15: =IFERROR(+H15/(P15+Q15+R15+S15+T15),0) -> 0
A16: 218*12 PET BOPP | B16: ='DAY1'!H16 -> 36 | C16: 0 | D16: 0 | E16: 0 | F16: 0 | G16: 0 | H16: =+(Table14[[#This Row],[OPENING ]]+Table14[[#This Row],[RECEIPTS]]+Table14[[#This Row],[RETURNS]])-(Table14[[#This Row],[ISSUES]]+Table14[[#This Row],[EXCHANGED]]+Table14[[#This Row],[SALES]]) -> 36 | I16: 36 | J16: =+I16-H16 -> 0 | K16: =+'DAY1'!K16+'DAY2'!C16 -> 0 | L16: =+'DAY1'!L16+'DAY2'!D16 -> 0 | M16: =+'DAY1'!M16+'DAY2'!E16 -> 0 | N16: =+'DAY1'!N16+'DAY2'!F16 -> 0 | O16: =+'DAY1'!O16+'DAY2'!G16 -> 0 | P16: =+Table14[[#This Row],[RECEIPTS TO]]/1 -> 0 | Q16: =+Table14[[#This Row],[RETURNS ]]/1 -> 0 | R16: =+Table14[[#This Row],[EXCHANGED TO]]/1 -> 0 | S16: =+Table14[[#This Row],[SALES TO]]/1 -> 0 | T16: =+Table14[[#This Row],[ISSUES TO]]/1 -> 0 | U16: =IFERROR(+H16/(P16+Q16+R16+S16+T16),0) -> 0
A17: 220*12 PET BOPP | B17: ='DAY1'!H17 -> 0 | C17: 0 | D17: 0 | E17: 0 | F17: 0 | G17: 0 | H17: =+(Table14[[#This Row],[OPENING ]]+Table14[[#This Row],[RECEIPTS]]+Table14[[#This Row],[RETURNS]])-(Table14[[#This Row],[ISSUES]]+Table14[[#This Row],[EXCHANGED]]+Table14[[#This Row],[SALES]]) -> 0 | J17: =+I17-H17 -> 0 | K17: =+'DAY1'!K17+'DAY2'!C17 -> 0 | L17: =+'DAY1'!L17+'DAY2'!D17 -> 0 | M17: =+'DAY1'!M17+'DAY2'!E17 -> 0 | N17: =+'DAY1'!N17+'DAY2'!F17 -> 0 | O17: =+'DAY1'!O17+'DAY2'!G17 -> 0 | P17: =+Table14[[#This Row],[RECEIPTS TO]]/1 -> 0 | Q17: =+Table14[[#This Row],[RETURNS ]]/1 -> 0 | R17: =+Table14[[#This Row],[EXCHANGED TO]]/1 -> 0 | S17: =+Table14[[#This Row],[SALES TO]]/1 -> 0 | T17: =+Table14[[#This Row],[ISSUES TO]]/1 -> 0 | U17: =IFERROR(+H17/(P17+Q17+R17+S17+T17),0) -> 0
A18: 229*12 PET BOPP | B18: ='DAY1'!H18 -> 0 | C18: 0 | D18: 0 | E18: 0 | F18: 0 | G18: 0 | H18: =+(Table14[[#This Row],[OPENING ]]+Table14[[#This Row],[RECEIPTS]]+Table14[[#This Row],[RETURNS]])-(Table14[[#This Row],[ISSUES]]+Table14[[#This Row],[EXCHANGED]]+Table14[[#This Row],[SALES]]) -> 0 | J18: =+I18-H18 -> 0 | K18: =+'DAY1'!K18+'DAY2'!C18 -> 0 | L18: =+'DAY1'!L18+'DAY2'!D18 -> 0 | M18: =+'DAY1'!M18+'DAY2'!E18 -> 0 | N18: =+'DAY1'!N18+'DAY2'!F18 -> 0 | O18: =+'DAY1'!O18+'DAY2'!G18 -> 0 | P18: =+Table14[[#This Row],[RECEIPTS TO]]/1 -> 0 | Q18: =+Table14[[#This Row],[RETURNS ]]/1 -> 0 | R18: =+Table14[[#This Row],[EXCHANGED TO]]/1 -> 0 | S18: =+Table14[[#This Row],[SALES TO]]/1 -> 0 | T18: =+Table14[[#This Row],[ISSUES TO]]/1 -> 0 | U18: =IFERROR(+H18/(P18+Q18+R18+S18+T18),0) -> 0
A19: 230*19 PET BOPP | B19: ='DAY1'!H19 -> 27 | C19: 0 | D19: 0 | E19: 0 | F19: 0 | G19: 0 | H19: =+(Table14[[#This Row],[OPENING ]]+Table14[[#This Row],[RECEIPTS]]+Table14[[#This Row],[RETURNS]])-(Table14[[#This Row],[ISSUES]]+Table14[[#This Row],[EXCHANGED]]+Table14[[#This Row],[SALES]]) -> 27 | I19: 27 | J19: =+I19-H19 -> 0 | K19: =+'DAY1'!K19+'DAY2'!C19 -> 0 | L19: =+'DAY1'!L19+'DAY2'!D19 -> 0 | M19: =+'DAY1'!M19+'DAY2'!E19 -> 0 | N19: =+'DAY1'!N19+'DAY2'!F19 -> 0 | O19: =+'DAY1'!O19+'DAY2'!G19 -> 0 | P19: =+Table14[[#This Row],[RECEIPTS TO]]/1 -> 0 | Q19: =+Table14[[#This Row],[RETURNS ]]/1 -> 0 | R19: =+Table14[[#This Row],[EXCHANGED TO]]/1 -> 0 | S19: =+Table14[[#This Row],[SALES TO]]/1 -> 0 | T19: =+Table14[[#This Row],[ISSUES TO]]/1 -> 0 | U19: =IFERROR(+H19/(P19+Q19+R19+S19+T19),0) -> 0
A20: 190*12 PET BOPP | B20: ='DAY1'!H20 -> 228.5 | C20: 0 | D20: 0 | E20: 0 | F20: 0 | G20: 0 | H20: =+(Table14[[#This Row],[OPENING ]]+Table14[[#This Row],[RECEIPTS]]+Table14[[#This Row],[RETURNS]])-(Table14[[#This Row],[ISSUES]]+Table14[[#This Row],[EXCHANGED]]+Table14[[#This Row],[SALES]]) -> 228.5 | I20: 228.5 | J20: =+I20-H20 -> 0 | K20: =+'DAY1'!K20+'DAY2'!C20 -> 0 | L20: =+'DAY1'!L20+'DAY2'!D20 -> 0 | M20: =+'DAY1'!M20+'DAY2'!E20 -> 0 | N20: =+'DAY1'!N20+'DAY2'!F20 -> 0 | O20: =+'DAY1'!O20+'DAY2'!G20 -> 0 | P20: =+Table14[[#This Row],[RECEIPTS TO]]/1 -> 0 | Q20: =+Table14[[#This Row],[RETURNS ]]/1 -> 0 | R20: =+Table14[[#This Row],[EXCHANGED TO]]/1 -> 0 | S20: =+Table14[[#This Row],[SALES TO]]/1 -> 0 | T20: =+Table14[[#This Row],[ISSUES TO]]/1 -> 0 | U20: =IFERROR(+H20/(P20+Q20+R20+S20+T20),0) -> 0
A21: 170 *12 PET BOPP | B21: ='DAY1'!H21 -> 70 | C21: 0 | D21: 0 | E21: 0 | F21: 0 | G21: 0 | H21: =+(Table14[[#This Row],[OPENING ]]+Table14[[#This Row],[RECEIPTS]]+Table14[[#This Row],[RETURNS]])-(Table14[[#This Row],[ISSUES]]+Table14[[#This Row],[EXCHANGED]]+Table14[[#This Row],[SALES]]) -> 70 | I21: 70 | J21: =+I21-H21 -> 0 | K21: =+'DAY1'!K21+'DAY2'!C21 -> 0 | L21: =+'DAY1'!L21+'DAY2'!D21 -> 0 | M21: =+'DAY1'!M21+'DAY2'!E21 -> 0 | N21: =+'DAY1'!N21+'DAY2'!F21 -> 0 | O21: =+'DAY1'!O21+'DAY2'!G21 -> 0 | P21: =+Table14[[#This Row],[RECEIPTS TO]]/1 -> 0 | Q21: =+Table14[[#This Row],[RETURNS ]]/1 -> 0 | R21: =+Table14[[#This Row],[EXCHANGED TO]]/1 -> 0 | S21: =+Table14[[#This Row],[SALES TO]]/1 -> 0 | T21: =+Table14[[#This Row],[ISSUES TO]]/1 -> 0 | U21: =IFERROR(+H21/(P21+Q21+R21+S21+T21),0) -> 0
A22: 140*12 PET BOPP | B22: ='DAY1'!H22 -> 14 | C22: 0 | D22: 0 | E22: 0 | F22: 0 | G22: 0 | H22: =+(Table14[[#This Row],[OPENING ]]+Table14[[#This Row],[RECEIPTS]]+Table14[[#This Row],[RETURNS]])-(Table14[[#This Row],[ISSUES]]+Table14[[#This Row],[EXCHANGED]]+Table14[[#This Row],[SALES]]) -> 14 | I22: 14 | J22: =+I22-H22 -> 0 | K22: =+'DAY1'!K22+'DAY2'!C22 -> 0 | L22: =+'DAY1'!L22+'DAY2'!D22 -> 0 | M22: =+'DAY1'!M22+'DAY2'!E22 -> 0 | N22: =+'DAY1'!N22+'DAY2'!F22 -> 0 | O22: =+'DAY1'!O22+'DAY2'!G22 -> 0 | P22: =+Table14[[#This Row],[RECEIPTS TO]]/1 -> 0 | Q22: =+Table14[[#This Row],[RETURNS ]]/1 -> 0 | R22: =+Table14[[#This Row],[EXCHANGED TO]]/1 -> 0 | S22: =+Table14[[#This Row],[SALES TO]]/1 -> 0 | T22: =+Table14[[#This Row],[ISSUES TO]]/1 -> 0 | U22: =IFERROR(+H22/(P22+Q22+R22+S22+T22),0) -> 0
A23: 290*12 PET BOPP | B23: ='DAY1'!H23 -> 70 | C23: 0 | D23: 0 | E23: 0 | F23: 0 | G23: 0 | H23: =+(Table14[[#This Row],[OPENING ]]+Table14[[#This Row],[RECEIPTS]]+Table14[[#This Row],[RETURNS]])-(Table14[[#This Row],[ISSUES]]+Table14[[#This Row],[EXCHANGED]]+Table14[[#This Row],[SALES]]) -> 70 | I23: 70 | J23: =+I23-H23 -> 0 | K23: =+'DAY1'!K23+'DAY2'!C23 -> 0 | L23: =+'DAY1'!L23+'DAY2'!D23 -> 0 | M23: =+'DAY1'!M23+'DAY2'!E23 -> 0 | N23: =+'DAY1'!N23+'DAY2'!F23 -> 0 | O23: =+'DAY1'!O23+'DAY2'!G23 -> 0 | P23: =+Table14[[#This Row],[RECEIPTS TO]]/1 -> 0 | Q23: =+Table14[[#This Row],[RETURNS ]]/1 -> 0 | R23: =+Table14[[#This Row],[EXCHANGED TO]]/1 -> 0 | S23: =+Table14[[#This Row],[SALES TO]]/1 -> 0 | T23: =+Table14[[#This Row],[ISSUES TO]]/1 -> 0 | U23: =IFERROR(+H23/(P23+Q23+R23+S23+T23),0) -> 0
A24: 320*12 PET BOPP | B24: ='DAY1'!H24 -> 49 | C24: 0 | D24: 0 | E24: 0 | F24: 0 | G24: 0 | H24: =+(Table14[[#This Row],[OPENING ]]+Table14[[#This Row],[RECEIPTS]]+Table14[[#This Row],[RETURNS]])-(Table14[[#This Row],[ISSUES]]+Table14[[#This Row],[EXCHANGED]]+Table14[[#This Row],[SALES]]) -> 49 | I24: 49 | J24: =+I24-H24 -> 0 | K24: =+'DAY1'!K24+'DAY2'!C24 -> 0 | L24: =+'DAY1'!L24+'DAY2'!D24 -> 0 | M24: =+'DAY1'!M24+'DAY2'!E24 -> 0 | N24: =+'DAY1'!N24+'DAY2'!F24 -> 0 | O24: =+'DAY1'!O24+'DAY2'!G24 -> 0 | P24: =+Table14[[#This Row],[RECEIPTS TO]]/1 -> 0 | Q24: =+Table14[[#This Row],[RETURNS ]]/1 -> 0 | R24: =+Table14[[#This Row],[EXCHANGED TO]]/1 -> 0 | S24: =+Table14[[#This Row],[SALES TO]]/1 -> 0 | T24: =+Table14[[#This Row],[ISSUES TO]]/1 -> 0 | U24: =IFERROR(+H24/(P24+Q24+R24+S24+T24),0) -> 0
B25: ='DAY1'!H25 -> 0 | C25: 0 | D25: 0 | E25: 0 | F25: 0 | G25: 0 | H25: =+(Table14[[#This Row],[OPENING ]]+Table14[[#This Row],[RECEIPTS]]+Table14[[#This Row],[RETURNS]])-(Table14[[#This Row],[ISSUES]]+Table14[[#This Row],[EXCHANGED]]+Table14[[#This Row],[SALES]]) -> 0 | J25: =+I25-H25 -> 0 | K25: =+'DAY1'!K25+'DAY2'!C25 -> 0 | L25: =+'DAY1'!L25+'DAY2'!D25 -> 0 | M25: =+'DAY1'!M25+'DAY2'!E25 -> 0 | N25: =+'DAY1'!N25+'DAY2'!F25 -> 0 | O25: =+'DAY1'!O25+'DAY2'!G25 -> 0 | P25: =+Table14[[#This Row],[RECEIPTS TO]]/1 -> 0 | Q25: =+Table14[[#This Row],[RETURNS ]]/1 -> 0 | R25: =+Table14[[#This Row],[EXCHANGED TO]]/1 -> 0 | S25: =+Table14[[#This Row],[SALES TO]]/1 -> 0 | T25: =+Table14[[#This Row],[ISSUES TO]]/1 -> 0 | U25: =IFERROR(+H25/(P25+Q25+R25+S25+T25),0) -> 0
A26: CLEAR BOPP | B26: ='DAY1'!H26 -> 0 | C26: 0 | D26: 0 | E26: 0 | F26: 0 | G26: 0 | H26: =+(Table14[[#This Row],[OPENING ]]+Table14[[#This Row],[RECEIPTS]]+Table14[[#This Row],[RETURNS]])-(Table14[[#This Row],[ISSUES]]+Table14[[#This Row],[EXCHANGED]]+Table14[[#This Row],[SALES]]) -> 0 | J26: =+I26-H26 -> 0 | K26: =+'DAY1'!K26+'DAY2'!C26 -> 0 | L26: =+'DAY1'!L26+'DAY2'!D26 -> 0 | M26: =+'DAY1'!M26+'DAY2'!E26 -> 0 | N26: =+'DAY1'!N26+'DAY2'!F26 -> 0 | O26: =+'DAY1'!O26+'DAY2'!G26 -> 0 | P26: =+Table14[[#This Row],[RECEIPTS TO]]/1 -> 0 | Q26: =+Table14[[#This Row],[RETURNS ]]/1 -> 0 | R26: =+Table14[[#This Row],[EXCHANGED TO]]/1 -> 0 | S26: =+Table14[[#This Row],[SALES TO]]/1 -> 0 | T26: =+Table14[[#This Row],[ISSUES TO]]/1 -> 0 | U26: =IFERROR(+H26/(P26+Q26+R26+S26+T26),0) -> 0
A27: 755*18 CLEAR BOPP | B27: ='DAY1'!H27 -> 506.2 | C27: 0 | D27: 0 | E27: 0 | F27: 0 | G27: 0 | H27: =+(Table14[[#This Row],[OPENING ]]+Table14[[#This Row],[RECEIPTS]]+Table14[[#This Row],[RETURNS]])-(Table14[[#This Row],[ISSUES]]+Table14[[#This Row],[EXCHANGED]]+Table14[[#This Row],[SALES]]) -> 506.2 | I27: 506.2 | J27: =+I27-H27 -> 0 | K27: =+'DAY1'!K27+'DAY2'!C27 -> 0 | L27: =+'DAY1'!L27+'DAY2'!D27 -> 0 | M27: =+'DAY1'!M27+'DAY2'!E27 -> 0 | N27: =+'DAY1'!N27+'DAY2'!F27 -> 0 | O27: =+'DAY1'!O27+'DAY2'!G27 -> 0 | P27: =+Table14[[#This Row],[RECEIPTS TO]]/1 -> 0 | Q27: =+Table14[[#This Row],[RETURNS ]]/1 -> 0 | R27: =+Table14[[#This Row],[EXCHANGED TO]]/1 -> 0 | S27: =+Table14[[#This Row],[SALES TO]]/1 -> 0 | T27: =+Table14[[#This Row],[ISSUES TO]]/1 -> 0 | U27: =IFERROR(+H27/(P27+Q27+R27+S27+T27),0) -> 0
A28: 300 MM X 20 UM COOL CYCLONE | B28: ='DAY1'!H28 -> 0 | C28: 0 | D28: 0 | E28: 0 | F28: 0 | G28: 0 | H28: =+(Table14[[#This Row],[OPENING ]]+Table14[[#This Row],[RECEIPTS]]+Table14[[#This Row],[RETURNS]])-(Table14[[#This Row],[ISSUES]]+Table14[[#This Row],[EXCHANGED]]+Table14[[#This Row],[SALES]]) -> 0 | J28: =+I28-H28 -> 0 | K28: =+'DAY1'!K28+'DAY2'!C28 -> 0 | L28: =+'DAY1'!L28+'DAY2'!D28 -> 0 | M28: =+'DAY1'!M28+'DAY2'!E28 -> 0 | N28: =+'DAY1'!N28+'DAY2'!F28 -> 0 | O28: =+'DAY1'!O28+'DAY2'!G28 -> 0 | P28: =+Table14[[#This Row],[RECEIPTS TO]]/1 -> 0 | Q28: =+Table14[[#This Row],[RETURNS ]]/1 -> 0 | R28: =+Table14[[#This Row],[EXCHANGED TO]]/1 -> 0 | S28: =+Table14[[#This Row],[SALES TO]]/1 -> 0 | T28: =+Table14[[#This Row],[ISSUES TO]]/1 -> 0 | U28: =IFERROR(+H28/(P28+Q28+R28+S28+T28),0) -> 0
A29: 570 MM X 20 UM COOL CYCLONE | B29: ='DAY1'!H29 -> 318.3 | C29: 0 | D29: 0 | E29: 0 | F29: 0 | G29: 0 | H29: =+(Table14[[#This Row],[OPENING ]]+Table14[[#This Row],[RECEIPTS]]+Table14[[#This Row],[RETURNS]])-(Table14[[#This Row],[ISSUES]]+Table14[[#This Row],[EXCHANGED]]+Table14[[#This Row],[SALES]]) -> 318.3 | I29: 318.3 | J29: =+I29-H29 -> 0 | K29: =+'DAY1'!K29+'DAY2'!C29 -> 0 | L29: =+'DAY1'!L29+'DAY2'!D29 -> 0 | M29: =+'DAY1'!M29+'DAY2'!E29 -> 0 | N29: =+'DAY1'!N29+'DAY2'!F29 -> 0 | O29: =+'DAY1'!O29+'DAY2'!G29 -> 0 | P29: =+Table14[[#This Row],[RECEIPTS TO]]/1 -> 0 | Q29: =+Table14[[#This Row],[RETURNS ]]/1 -> 0 | R29: =+Table14[[#This Row],[EXCHANGED TO]]/1 -> 0 | S29: =+Table14[[#This Row],[SALES TO]]/1 -> 0 | T29: =+Table14[[#This Row],[ISSUES TO]]/1 -> 0 | U29: =IFERROR(+H29/(P29+Q29+R29+S29+T29),0) -> 0
A30: 550 MM X 20 UM COOL CYCLONE | B30: ='DAY1'!H30 -> 0 | C30: 0 | D30: 0 | E30: 0 | F30: 0 | G30: 0 | H30: =+(Table14[[#This Row],[OPENING ]]+Table14[[#This Row],[RECEIPTS]]+Table14[[#This Row],[RETURNS]])-(Table14[[#This Row],[ISSUES]]+Table14[[#This Row],[EXCHANGED]]+Table14[[#This Row],[SALES]]) -> 0 | J30: =+I30-H30 -> 0 | K30: =+'DAY1'!K30+'DAY2'!C30 -> 0 | L30: =+'DAY1'!L30+'DAY2'!D30 -> 0 | M30: =+'DAY1'!M30+'DAY2'!E30 -> 0 | N30: =+'DAY1'!N30+'DAY2'!F30 -> 0 | O30: =+'DAY1'!O30+'DAY2'!G30 -> 0 | P30: =+Table14[[#This Row],[RECEIPTS TO]]/1 -> 0 | Q30: =+Table14[[#This Row],[RETURNS ]]/1 -> 0 | R30: =+Table14[[#This Row],[EXCHANGED TO]]/1 -> 0 | S30: =+Table14[[#This Row],[SALES TO]]/1 -> 0 | T30: =+Table14[[#This Row],[ISSUES TO]]/1 -> 0 | U30: =IFERROR(+H30/(P30+Q30+R30+S30+T30),0) -> 0
A31: 1100 MM X 30 UM COOL CYCLONE | B31: ='DAY1'!H31 -> 0 | C31: 0 | D31: 0 | E31: 0 | F31: 0 | G31: 0 | H31: =+(Table14[[#This Row],[OPENING ]]+Table14[[#This Row],[RECEIPTS]]+Table14[[#This Row],[RETURNS]])-(Table14[[#This Row],[ISSUES]]+Table14[[#This Row],[EXCHANGED]]+Table14[[#This Row],[SALES]]) -> 0 | J31: =+I31-H31 -> 0 | K31: =+'DAY1'!K31+'DAY2'!C31 -> 0 | L31: =+'DAY1'!L31+'DAY2'!D31 -> 0 | M31: =+'DAY1'!M31+'DAY2'!E31 -> 0 | N31: =+'DAY1'!N31+'DAY2'!F31 -> 0 | O31: =+'DAY1'!O31+'DAY2'!G31 -> 0 | P31: =+Table14[[#This Row],[RECEIPTS TO]]/1 -> 0 | Q31: =+Table14[[#This Row],[RETURNS ]]/1 -> 0 | R31: =+Table14[[#This Row],[EXCHANGED TO]]/1 -> 0 | S31: =+Table14[[#This Row],[SALES TO]]/1 -> 0 | T31: =+Table14[[#This Row],[ISSUES TO]]/1 -> 0 | U31: =IFERROR(+H31/(P31+Q31+R31+S31+T31),0) -> 0
A32: 1100 MM X 30 UM SRF | B32: ='DAY1'!H32 -> 0 | C32: 0 | D32: 0 | E32: 0 | F32: 0 | G32: 0 | H32: =+(Table14[[#This Row],[OPENING ]]+Table14[[#This Row],[RECEIPTS]]+Table14[[#This Row],[RETURNS]])-(Table14[[#This Row],[ISSUES]]+Table14[[#This Row],[EXCHANGED]]+Table14[[#This Row],[SALES]]) -> 0 | J32: =+I32-H32 -> 0 | K32: =+'DAY1'!K32+'DAY2'!C32 -> 0 | L32: =+'DAY1'!L32+'DAY2'!D32 -> 0 | M32: =+'DAY1'!M32+'DAY2'!E32 -> 0 | N32: =+'DAY1'!N32+'DAY2'!F32 -> 0 | O32: =+'DAY1'!O32+'DAY2'!G32 -> 0 | P32: =+Table14[[#This Row],[RECEIPTS TO]]/1 -> 0 | Q32: =+Table14[[#This Row],[RETURNS ]]/1 -> 0 | R32: =+Table14[[#This Row],[EXCHANGED TO]]/1 -> 0 | S32: =+Table14[[#This Row],[SALES TO]]/1 -> 0 | T32: =+Table14[[#This Row],[ISSUES TO]]/1 -> 0 | U32: =IFERROR(+H32/(P32+Q32+R32+S32+T32),0) -> 0
A33: 390 MM X 20 UM | B33: ='DAY1'!H33 -> 0 | C33: 0 | D33: 0 | E33: 0 | F33: 0 | G33: 0 | H33: =+(Table14[[#This Row],[OPENING ]]+Table14[[#This Row],[RECEIPTS]]+Table14[[#This Row],[RETURNS]])-(Table14[[#This Row],[ISSUES]]+Table14[[#This Row],[EXCHANGED]]+Table14[[#This Row],[SALES]]) -> 0 | J33: =+I33-H33 -> 0 | K33: =+'DAY1'!K33+'DAY2'!C33 -> 0 | L33: =+'DAY1'!L33+'DAY2'!D33 -> 0 | M33: =+'DAY1'!M33+'DAY2'!E33 -> 0 | N33: =+'DAY1'!N33+'DAY2'!F33 -> 0 | O33: =+'DAY1'!O33+'DAY2'!G33 -> 0 | P33: =+Table14[[#This Row],[RECEIPTS TO]]/1 -> 0 | Q33: =+Table14[[#This Row],[RETURNS ]]/1 -> 0 | R33: =+Table14[[#This Row],[EXCHANGED TO]]/1 -> 0 | S33: =+Table14[[#This Row],[SALES TO]]/1 -> 0 | T33: =+Table14[[#This Row],[ISSUES TO]]/1 -> 0 | U33: =IFERROR(+H33/(P33+Q33+R33+S33+T33),0) -> 0
A34: 550 MM X 30UM | B34: ='DAY1'!H34 -> 58.1 | C34: 0 | D34: 0 | E34: 0 | F34: 0 | G34: 0 | H34: =+(Table14[[#This Row],[OPENING ]]+Table14[[#This Row],[RECEIPTS]]+Table14[[#This Row],[RETURNS]])-(Table14[[#This Row],[ISSUES]]+Table14[[#This Row],[EXCHANGED]]+Table14[[#This Row],[SALES]]) -> 58.1 | I34: 58.1 | J34: =+I34-H34 -> 0 | K34: =+'DAY1'!K34+'DAY2'!C34 -> 0 | L34: =+'DAY1'!L34+'DAY2'!D34 -> 0 | M34: =+'DAY1'!M34+'DAY2'!E34 -> 0 | N34: =+'DAY1'!N34+'DAY2'!F34 -> 0 | O34: =+'DAY1'!O34+'DAY2'!G34 -> 0 | P34: =+Table14[[#This Row],[RECEIPTS TO]]/1 -> 0 | Q34: =+Table14[[#This Row],[RETURNS ]]/1 -> 0 | R34: =+Table14[[#This Row],[EXCHANGED TO]]/1 -> 0 | S34: =+Table14[[#This Row],[SALES TO]]/1 -> 0 | T34: =+Table14[[#This Row],[ISSUES TO]]/1 -> 0 | U34: =IFERROR(+H34/(P34+Q34+R34+S34+T34),0) -> 0
A35: 400 MM X 30 UM | B35: ='DAY1'!H35 -> 0 | C35: 0 | D35: 0 | E35: 0 | F35: 0 | G35: 0 | H35: =+(Table14[[#This Row],[OPENING ]]+Table14[[#This Row],[RECEIPTS]]+Table14[[#This Row],[RETURNS]])-(Table14[[#This Row],[ISSUES]]+Table14[[#This Row],[EXCHANGED]]+Table14[[#This Row],[SALES]]) -> 0 | J35: =+I35-H35 -> 0 | K35: =+'DAY1'!K35+'DAY2'!C35 -> 0 | L35: =+'DAY1'!L35+'DAY2'!D35 -> 0 | M35: =+'DAY1'!M35+'DAY2'!E35 -> 0 | N35: =+'DAY1'!N35+'DAY2'!F35 -> 0 | O35: =+'DAY1'!O35+'DAY2'!G35 -> 0 | P35: =+Table14[[#This Row],[RECEIPTS TO]]/1 -> 0 | Q35: =+Table14[[#This Row],[RETURNS ]]/1 -> 0 | R35: =+Table14[[#This Row],[EXCHANGED TO]]/1 -> 0 | S35: =+Table14[[#This Row],[SALES TO]]/1 -> 0 | T35: =+Table14[[#This Row],[ISSUES TO]]/1 -> 0 | U35: =IFERROR(+H35/(P35+Q35+R35+S35+T35),0) -> 0
A36: 640 MM X 20 UM | B36: ='DAY1'!H36 -> 31.35 | C36: 0 | D36: 0 | E36: 0 | F36: 0 | G36: 0 | H36: =+(Table14[[#This Row],[OPENING ]]+Table14[[#This Row],[RECEIPTS]]+Table14[[#This Row],[RETURNS]])-(Table14[[#This Row],[ISSUES]]+Table14[[#This Row],[EXCHANGED]]+Table14[[#This Row],[SALES]]) -> 31.35 | I36: 31.35 | J36: =+I36-H36 -> 0 | K36: =+'DAY1'!K36+'DAY2'!C36 -> 0 | L36: =+'DAY1'!L36+'DAY2'!D36 -> 0 | M36: =+'DAY1'!M36+'DAY2'!E36 -> 0 | N36: =+'DAY1'!N36+'DAY2'!F36 -> 0 | O36: =+'DAY1'!O36+'DAY2'!G36 -> 0 | P36: =+Table14[[#This Row],[RECEIPTS TO]]/1 -> 0 | Q36: =+Table14[[#This Row],[RETURNS ]]/1 -> 0 | R36: =+Table14[[#This Row],[EXCHANGED TO]]/1 -> 0 | S36: =+Table14[[#This Row],[SALES TO]]/1 -> 0 | T36: =+Table14[[#This Row],[ISSUES TO]]/1 -> 0 | U36: =IFERROR(+H36/(P36+Q36+R36+S36+T36),0) -> 0
A37: 400 MM x 20 UM COOL CYCLONE | B37: ='DAY1'!H37 -> 0 | C37: 0 | D37: 0 | E37: 0 | F37: 0 | G37: 0 | H37: =+(Table14[[#This Row],[OPENING ]]+Table14[[#This Row],[RECEIPTS]]+Table14[[#This Row],[RETURNS]])-(Table14[[#This Row],[ISSUES]]+Table14[[#This Row],[EXCHANGED]]+Table14[[#This Row],[SALES]]) -> 0 | J37: =+I37-H37 -> 0 | K37: =+'DAY1'!K37+'DAY2'!C37 -> 0 | L37: =+'DAY1'!L37+'DAY2'!D37 -> 0 | M37: =+'DAY1'!M37+'DAY2'!E37 -> 0 | N37: =+'DAY1'!N37+'DAY2'!F37 -> 0 | O37: =+'DAY1'!O37+'DAY2'!G37 -> 0 | P37: =+Table14[[#This Row],[RECEIPTS TO]]/1 -> 0 | Q37: =+Table14[[#This Row],[RETURNS ]]/1 -> 0 | R37: =+Table14[[#This Row],[EXCHANGED TO]]/1 -> 0 | S37: =+Table14[[#This Row],[SALES TO]]/1 -> 0 | T37: =+Table14[[#This Row],[ISSUES TO]]/1 -> 0 | U37: =IFERROR(+H37/(P37+Q37+R37+S37+T37),0) -> 0
A38: TOTAL BOPP | B38: =SUM(B5:B37) -> 1576.05 | C38: =SUM(C5:C37) -> 0 | D38: =SUM(D5:D37) -> 0 | E38: =SUM(E5:E37) -> 0 | F38: =SUM(F5:F37) -> 0 | G38: =SUM(G5:G37) -> 0 | H38: =SUM(H5:H37) -> 1576.05 | I38: =SUM(I5:I37) -> 1576.05 | ... U38: =SUM(U5:U37) -> 0
A39: TAEJIN BOPP
A40: HEAT SEALABLE CLEAR BOPP FILM TREATED OUTSIDE
...

Sheet DAY3
A1: BOPP STOCK MOVEMENT REPORT AS OF 1/9/26
A2: DESCRIPTION AND CODE | B2: OPENING | C2: RECEIPTS | D2: RETURNS | E2: EXCHANGED | F2: SALES | G2: ISSUES | H2: THEORETICAL | I2: PHYSICAL | J2: R/MATERIAL | K2: RECEIPTS TO | L2: RETURNS | M2: EXCHANGED TO | N2: SALES TO | O2: ISSUES TO | P2: AVE RECEIPTS | Q2: AVE RETURNS | R2: AVE EXCHANGED | S2: AVE SALES | T2: AVE ISSUES | U2: STOCK
B3: STOCK | H3: CLOSING STOCK | I3: CLOSING STOCK | K3: DATE | L3: TO DATE | M3: DATE | N3: DATE | O3: DATE | P3: PER DAY | Q3: PER DAY | R3: PER DAY | T3: PER DAY | U3: DAYS
A4: BOPP : CLEAR & PET
B5: ='DAY2'!H5 -> 0 | C5: 0 | D5: 0 | E5: 0 | F5: 0 | G5: 0 | H5: =+(Table1433[[#This Row],[OPENING ]]+Table1433[[#This Row],[RECEIPTS]]+Table1433[[#This Row],[RETURNS]])-(Table1433[[#This Row],[EXCHANGED]]+Table1433[[#This Row],[SALES]]+Table1433[[#This Row],[ISSUES]]) -> 0 | I5: 0 | J5: =+I5-H5 -> 0 | K5: ='DAY2'!K5+'DAY3'!C5 -> 0 | L5: ='DAY2'!L5+'DAY3'!D5 -> 0 | M5: ='DAY2'!M5+'DAY3'!E5 -> 0 | N5: ='DAY2'!N5+'DAY3'!F5 -> 0 | O5: ='DAY2'!O5+'DAY3'!G5 -> 0 | P5: =+K5/3 -> 0 | Q5: =+L5/3 -> 0 | R5: =+M5/3 -> 0 | S5: =+N5/3 -> 0 | T5: =+O5/3 -> 0 | U5: =IFERROR(+H5/(P5+Q5+R5+S5+T5),0) -> 0
B6: ='DAY2'!H6 -> 0 | C6: 0 | D6: 0 | E6: 0 | F6: 0 | G6: 0 | H6: =+(Table1433[[#This Row],[OPENING ]]+Table1433[[#This Row],[RECEIPTS]]+Table1433[[#This Row],[RETURNS]])-(Table1433[[#This Row],[EXCHANGED]]+Table1433[[#This Row],[SALES]]+Table1433[[#This Row],[ISSUES]]) -> 0 | I6: 0 | J6: =+I6-H6 -> 0 | K6: ='DAY2'!K6+'DAY3'!C6 -> 0 | L6: ='DAY2'!L6+'DAY3'!D6 -> 0 | M6: ='DAY2'!M6+'DAY3'!E6 -> 0 | N6: ='DAY2'!N6+'DAY3'!F6 -> 0 | O6: ='DAY2'!O6+'DAY3'!G6 -> 0 | P6: =+K6/3 -> 0 | Q6: =+L6/3 -> 0 | R6: =+M6/3 -> 0 | S6: =+N6/3 -> 0 | T6: =+O6/3 -> 0 | U6: =IFERROR(+H6/(P6+Q6+R6+S6+T6),0) -> 0
B7: ='DAY2'!H7 -> 0 | C7: 0 | D7: 0 | E7: 0 | F7: 0 | G7: 0 | H7: =+(Table1433[[#This Row],[OPENING ]]+Table1433[[#This Row],[RECEIPTS]]+Table1433[[#This Row],[RETURNS]])-(Table1433[[#This Row],[EXCHANGED]]+Table1433[[#This Row],[SALES]]+Table1433[[#This Row],[ISSUES]]) -> 0 | I7: 0 | J7: =+I7-H7 -> 0 | K7: ='DAY2'!K7+'DAY3'!C7 -> 0 | L7: ='DAY2'!L7+'DAY3'!D7 -> 0 | M7: ='DAY2'!M7+'DAY3'!E7 -> 0 | N7: ='DAY2'!N7+'DAY3'!F7 -> 0 | O7: ='DAY2'!O7+'DAY3'!G7 -> 0 | P7: =+K7/3 -> 0 | Q7: =+L7/3 -> 0 | R7: =+M7/3 -> 0 | S7: =+N7/3 -> 0 | T7: =+O7/3 -> 0 | U7: =IFERROR(+H7/(P7+Q7+R7+S7+T7),0) -> 0
A8: 110*12 PET BOPP | B8: ='DAY2'!H8 -> 8.5 | C8: 0 | D8: 0 | E8: 0 | F8: 0 | G8: 0 | H8: =+(Table1433[[#This Row],[OPENING ]]+Table1433[[#This Row],[RECEIPTS]]+Table1433[[#This Row],[RETURNS]])-(Table1433[[#This Row],[EXCHANGED]]+Table1433[[#This Row],[SALES]]+Table1433[[#This Row],[ISSUES]]) -> 8.5 | I8: 8.5 | J8: =+I8-H8 -> 0 | K8: ='DAY2'!K8+'DAY3'!C8 -> 0 | L8: ='DAY2'!L8+'DAY3'!D8 -> 0 | M8: ='DAY2'!M8+'DAY3'!E8 -> 0 | N8: ='DAY2'!N8+'DAY3'!F8 -> 0 | O8: ='DAY2'!O8+'DAY3'!G8 -> 0 | P8: =+K8/3 -> 0 | Q8: =+L8/3 -> 0 | R8: =+M8/3 -> 0 | S8: =+N8/3 -> 0 | T8: =+O8/3 -> 0 | U8: =IFERROR(+H8/(P8+Q8+R8+S8+T8),0) -> 0
A9: 115*12 PET BOPP | B9: ='DAY2'!H9 -> 15 | C9: 0 | D9: 0 | E9: 0 | F9: 0 | G9: 0 | H9: =+(Table1433[[#This Row],[OPENING ]]+Table1433[[#This Row],[RECEIPTS]]+Table1433[[#This Row],[RETURNS]])-(Table1433[[#This Row],[EXCHANGED]]+Table1433[[#This Row],[SALES]]+Table1433[[#This Row],[ISSUES]]) -> 15 | I9: 15 | J9: =+I9-H9 -> 0 | K9: ='DAY2'!K9+'DAY3'!C9 -> 0 | L9: ='DAY2'!L9+'DAY3'!D9 -> 0 | M9: ='DAY2'!M9+'DAY3'!E9 -> 0 | N9: ='DAY2'!N9+'DAY3'!F9 -> 0 | O9: ='DAY2'!O9+'DAY3'!G9 -> 0 | P9: =+K9/3 -> 0 | Q9: =+L9/3 -> 0 | R9: =+M9/3 -> 0 | S9: =+N9/3 -> 0 | T9: =+O9/3 -> 0 | U9: =IFERROR(+H9/(P9+Q9+R9+S9+T9),0) -> 0
A10: 125*12 PET BOPP | B10: ='DAY2'!H10 -> 18 | C10: 0 | D10: 0 | E10: 0 | F10: 0 | G10: 0 | H10: =+(Table1433[[#This Row],[OPENING ]]+Table1433[[#This Row],[RECEIPTS]]+Table1433[[#This Row],[RETURNS]])-(Table1433[[#This Row],[EXCHANGED]]+Table1433[[#This Row],[SALES]]+Table1433[[#This Row],[ISSUES]]) -> 18 | I10: 18 | J10: =+I10-H10 -> 0 | K10: ='DAY2'!K10+'DAY3'!C10 -> 0 | L10: ='DAY2'!L10+'DAY3'!D10 -> 0 | M10: ='DAY2'!M10+'DAY3'!E10 -> 0 | N10: ='DAY2'!N10+'DAY3'!F10 -> 0 | O10: ='DAY2'!O10+'DAY3'!G10 -> 0 | P10: =+K10/3 -> 0 | Q10: =+L10/3 -> 0 | R10: =+M10/3 -> 0 | S10: =+N10/3 -> 0 | T10: =+O10/3 -> 0 | U10: =IFERROR(+H10/(P10+Q10+R10+S10+T10),0) -> 0
A11: 129*12 PET BOPP | B11: ='DAY2'!H11 -> 10 | C11: 0 | D11: 0 | E11: 0 | F11: 0 | G11: 0 | H11: =+(Table1433[[#This Row],[OPENING ]]+Table1433[[#This Row],[RECEIPTS]]+Table1433[[#This Row],[RETURNS]])-(Table1433[[#This Row],[EXCHANGED]]+Table1433[[#This Row],[SALES]]+Table1433[[#This Row],[ISSUES]]) -> 10 | I11: 10 | J11: =+I11-H11 -> 0 | K11: ='DAY2'!K11+'DAY3'!C11 -> 0 | L11: ='DAY2'!L11+'DAY3'!D11 -> 0 | M11: ='DAY2'!M11+'DAY3'!E11 -> 0 | N11: ='DAY2'!N11+'DAY3'!F11 -> 0 | O11: ='DAY2'!O11+'DAY3'!G11 -> 0 | P11: =+K11/3 -> 0 | Q11: =+L11/3 -> 0 | R11: =+M11/3 -> 0 | S11: =+N11/3 -> 0 | T11: =+O11/3 -> 0 | U11: =IFERROR(+H11/(P11+Q11+R11+S11+T11),0) -> 0
A12: 150*12 PET BOPP | B12: ='DAY2'!H12 -> 28.6 | C12: 0 | D12: 0 | E12: 0 | F12: 0 | G12: 0 | H12: =+(Table1433[[#This Row],[OPENING ]]+Table1433[[#This Row],[RECEIPTS]]+Table1433[[#This Row],[RETURNS]])-(Table1433[[#This Row],[EXCHANGED]]+Table1433[[#This Row],[SALES]]+Table1433[[#This Row],[ISSUES]]) -> 28.6 | I12: 28.6 | J12: =+I12-H12 -> 0 | K12: ='DAY2'!K12+'DAY3'!C12 -> 0 | L12: ='DAY2'!L12+'DAY3'!D12 -> 0 | M12: ='DAY2'!M12+'DAY3'!E12 -> 0 | N12: ='DAY2'!N12+'DAY3'!F12 -> 0 | O12: ='DAY2'!O12+'DAY3'!G12 -> 0 | P12: =+K12/3 -> 0 | Q12: =+L12/3 -> 0 | R12: =+M12/3 -> 0 | S12: =+N12/3 -> 0 | T12: =+O12/3 -> 0 | U12: =IFERROR(+H12/(P12+Q12+R12+S12+T12),0) -> 0
A13: 155*12 PET BOPP | B13: ='DAY2'!H13 -> 23.5 | C13: 0 | D13: 0 | E13: 0 | F13: 0 | G13: 0 | H13: =+(Table1433[[#This Row],[OPENING ]]+Table1433[[#This Row],[RECEIPTS]]+Table1433[[#This Row],[RETURNS]])-(Table1433[[#This Row],[EXCHANGED]]+Table1433[[#This Row],[SALES]]+Table1433[[#This Row],[ISSUES]]) -> 23.5 | I13: 23.5 | J13: =+I13-H13 -> 0 | K13: ='DAY2'!K13+'DAY3'!C13 -> 0 | L13: ='DAY2'!L13+'DAY3'!D13 -> 0 | M13: ='DAY2'!M13+'DAY3'!E13 -> 0 | N13: ='DAY2'!N13+'DAY3'!F13 -> 0 | O13: ='DAY2'!O13+'DAY3'!G13 -> 0 | P13: =+K13/3 -> 0 | Q13: =+L13/3 -> 0 | R13: =+M13/3 -> 0 | S13: =+N13/3 -> 0 | T13: =+O13/3 -> 0 | U13: =IFERROR(+H13/(P13+Q13+R13+S13+T13),0) -> 0
A14: 160*12 PET BOPP | B14: ='DAY2'!H14 -> 30.5 | C14: 0 | D14: 0 | E14: 0 | F14: 0 | G14: 0 | H14: =+(Table1433[[#This Row],[OPENING ]]+Table1433[[#This Row],[RECEIPTS]]+Table1433[[#This Row],[RETURNS]])-(Table1433[[#This Row],[EXCHANGED]]+Table1433[[#This Row],[SALES]]+Table1433[[#This Row],[ISSUES]]) -> 30.5 | I14: 30.5 | J14: =+I14-H14 -> 0 | K14: ='DAY2'!K14+'DAY3'!C14 -> 0 | L14: ='DAY2'!L14+'DAY3'!D14 -> 0 | M14: ='DAY2'!M14+'DAY3'!E14 -> 0 | N14: ='DAY2'!N14+'DAY3'!F14 -> 0 | O14: ='DAY2'!O14+'DAY3'!G14 -> 0 | P14: =+K14/3 -> 0 | Q14: =+L14/3 -> 0 | R14: =+M14/3 -> 0 | S14: =+N14/3 -> 0 | T14: =+O14/3 -> 0 | U14: =IFERROR(+H14/(P14+Q14+R14+S14+T14),0) -> 0
A15: 165*12 PET BOPP | B15: ='DAY2'!H15 -> 33.5 | C15: 0 | D15: 0 | E15: 0 | F15: 0 | G15: 0 | H15: =+(Table1433[[#This Row],[OPENING ]]+Table1433[[#This Row],[RECEIPTS]]+Table1433[[#This Row],[RETURNS]])-(Table1433[[#This Row],[EXCHANGED]]+Table1433[[#This Row],[SALES]]+Table1433[[#This Row],[ISSUES]]) -> 33.5 | I15: 33.5 | J15: =+I15-H15 -> 0 | K15: ='DAY2'!K15+'DAY3'!C15 -> 0 | L15: ='DAY2'!L15+'DAY3'!D15 -> 0 | M15: ='DAY2'!M15+'DAY3'!E15 -> 0 | N15: ='DAY2'!N15+'DAY3'!F15 -> 0 | O15: ='DAY2'!O15+'DAY3'!G15 -> 0 | P15: =+K15/3 -> 0 | Q15: =+L15/3 -> 0 | R15: =+M15/3 -> 0 | S15: =+N15/3 -> 0 | T15: =+O15/3 -> 0 | U15: =IFERROR(+H15/(P15+Q15+R15+S15+T15),0) -> 0
